Workbook

Sheet 목차 (시트 이동)
B2: 1. 입 력 목 차 | F2: 3. 그 래 프 목 차
B4: 개 요 | C4: 이 동 | D4: 비 고 | F4: 개 요 | G4: 이 동 | H4: 비 고
B5: 월말 점검 입력 | D5: 월말 기입 필수 | F5: 월간 DIV 압력 Trend | H5: 월말 업데이트 필수
B6: DIV 배수 주기 | D6: 발생 시 기입 | F6: 2023년 Trend
B7: DIV 오일 보충 주기 | D7: 발생 시 기입 | F7: 2024년 Trend
B8: DIV 컴프레셔 교체 이력 | D8: 발생 시 기입 | F8: 2025년 Trend
F9: 2026년 Trend
B11: 2. 복 붙 목 차
B13: Raw 데이터 개요 | C13: 이 동 | D13: 비 고 | F13: 편집이 필요할 때 암호를 묻는다면? 7119
B14: 1월DIV 압력 데이터 | D14: 해당 월말 복붙
B15: 2월DIV 압력 데이터 | D15: 해당 월말 복붙
B16: 3월DIV 압력 데이터 | D16: 해당 월말 복붙
B17: 4월DIV 압력 데이터 | D17: 해당 월말 복붙
B18: 5월DIV 압력 데이터 | D18: 해당 월말 복붙
B19: 6월DIV 압력 데이터 | D19: 해당 월말 복붙
B20: 7월DIV 압력 데이터 | D20: 해당 월말 복붙
B21: 8월DIV 압력 데이터 | D21: 해당 월말 복붙
B22: 9월DIV 압력 데이터 | D22: 해당 월말 복붙
B23: 10월DIV 압력 데이터 | D23: 해당 월말 복붙
B24: 11월DIV 압력 데이터 | D24: 해당 월말 복붙
B25: 12월DIV 압력 데이터 | D25: 해당 월말 복붙
B26: 전체 DIV 압력 데이터 | D26: 년말 복붙 필수

Sheet 매 월말 점검시 입력
B2: =TODAY() -> 46073 | J2: <- 0. 회색 영역은 자동 생성됨.
B3: =MONTH(B2) -> 2 | C3: =YEAR(B2) -> 2026
B4: 년 | C4: 월 | D4: 층 | E4: 위치 | F4: 번호 | G4: 1차 | H4: 2차 | I4: 챔버
B5: =YEAR($B$2) -> 2026 | C5: =MONTH($B$2) -> 2 | D5: 9 | E5: 3 | F5: =D5&"-"&E5 -> 9-3 | G5: 5 | H5: 3.2 | I5: 5 | J5: <- 1. 주황색 영역에 점검표 순서대로 기입.
B6: =YEAR($B$2) -> 2026 | C6: =MONTH($B$2) -> 2 | D6: 8 | E6: 1 | F6: =D6&"-"&E6 -> 8-1 | G6: 4.8 | H6: 3.2 | I6: 5
B7: =YEAR($B$2) -> 2026 | C7: =MONTH($B$2) -> 2 | D7: 8 | E7: 2 | F7: =D7&"-"&E7 -> 8-2 | G7: 5 | H7: 3 | I7: 5
B8: =YEAR($B$2) -> 2026 | C8: =MONTH($B$2) -> 2 | D8: 8 | E8: 3 | F8: =D8&"-"&E8 -> 8-3 | G8: 5 | H8: 3.8 | I8: 5
B9: =YEAR($B$2) -> 2026 | C9: =MONTH($B$2) -> 2 | D9: 7 | E9: 1 | F9: =D9&"-"&E9 -> 7-1 | G9: 5.1 | H9: 3.2 | I9: 5.3
B10: =YEAR($B$2) -> 2026 | C10: =MONTH($B$2) -> 2 | D10: 7 | E10: 2 | F10: =D10&"-"&E10 -> 7-2 | G10: 5 | H10: 3.3 | I10: 5.8
B11: =YEAR($B$2) -> 2026 | C11: =MONTH($B$2) -> 2 | D11: 7 | E11: 3 | F11: =D11&"-"&E11 -> 7-3 | G11: 5.5 | H11: 3.4 | I11: 5
B12: =YEAR($B$2) -> 2026 | C12: =MONTH($B$2) -> 2 | D12: 6 | E12: 1 | F12: =D12&"-"&E12 -> 6-1 | G12: 6 | H12: 3.4 | I12: 6.3
B13: =YEAR($B$2) -> 2026 | C13: =MONTH($B$2) -> 2 | D13: 6 | E13: 2 | F13: =D13&"-"&E13 -> 6-2 | G13: 6 | H13: 3.3 | I13: 6
B14: =YEAR($B$2) -> 2026 | C14: =MONTH($B$2) -> 2 | D14: 6 | E14: 3 | F14: =D14&"-"&E14 -> 6-3 | G14: 6 | H14: 3.2 | I14: 6
B15: =YEAR($B$2) -> 2026 | C15: =MONTH($B$2) -> 2 | D15: 5 | E15: 1 | F15: =D15&"-"&E15 -> 5-1 | G15: 6.8 | H15: 3.5 | I15: 6.8
B16: =YEAR($B$2) -> 2026 | C16: =MONTH($B$2) -> 2 | D16: 5 | E16: 2 | F16: =D16&"-"&E16 -> 5-2 | G16: 6.6 | H16: 3.3 | I16: 6.7
B17: =YEAR($B$2) -> 2026 | C17: =MONTH($B$2) -> 2 | D17: 5 | E17: 3 | F17: =D17&"-"&E17 -> 5-3 | G17: 6.2 | H17: 3.8 | I17: 6.5
... B37: =YEAR($B$2) -> 2026 | C37: =MONTH($B$2) -> 2 | D37: -5 | E37: 2 | F37: =D37&"-"&E37 -> -5-2 | G37: 10 | H37: 3.7 | I37: 10
B38: =YEAR($B$2) -> 2026 | C38: =MONTH($B$2) -> 2 | D38: -5 | E38: 3 | F38: =D38&"-"&E38 -> -5-3 | G38: 10 | H38: 3 | I38: 10.1 | J38: <- 2. 굵은 선 영역 선택 후 복사 > 해당 월 시트 첫번째 셀 마우스 우클릭 > 선택하여 붙여넣기 > 값 붙여넣기 > 값

Sheet (년말) DIV 압력 RAW 복붙
A18: 1. 매년 12월이 끝나기 전, 회색 영역 선택 후 복사.
A19: 2. 표 바로 아랫 줄 첫 셀에서 마우스 우클릭 > 선택하여 붙여넣기> 값 붙여넣기> 값
A21: DIV Pressure Raw
A23: 년 | B23: 월 | C23: 년월 | D23: 층 | E23: 위치 | F23: 번호 | G23: 1차 | H23: 2차 | I23: 챔버
A24: ='1월'!A4 -> 2026 | B24: ='1월'!B4 -> 1 | C24: =RIGHT(A24,2)*100+'1월'!B4 -> 2601 | D24: ='1월'!C4 -> 9 | E24: ='1월'!D4 -> 3 | F24: ='1월'!E4 -> 9-3 | G24: =IFERROR(VLOOKUP($F24,'1월'!$E$4:$H$37,2,0),0) -> 4.9 | H24: =IFERROR(VLOOKUP($F24,'1월'!$E$4:$H$37,3,0),0) -> 3.2 | I24: =IFERROR(VLOOKUP($F24,'1월'!$E$4:$H$37,4,0),0) -> 4.7
A25: ='1월'!A5 -> 2026 | B25: ='1월'!B5 -> 1 | C25: =RIGHT(A25,2)*100+'1월'!B5 -> 2601 | D25: ='1월'!C5 -> 8 | E25: ='1월'!D5 -> 1 | F25: ='1월'!E5 -> 8-1 | G25: =IFERROR(VLOOKUP($F25,'1월'!$E$4:$H$37,2,0),0) -> 4.6 | H25: =IFERROR(VLOOKUP($F25,'1월'!$E$4:$H$37,3,0),0) -> 3.2 | I25: =IFERROR(VLOOKUP($F25,'1월'!$E$4:$H$37,4,0),0) -> 5
A26: ='1월'!A6 -> 2026 | B26: ='1월'!B6 -> 1 | C26: =RIGHT(A26,2)*100+'1월'!B6 -> 2601 | D26: ='1월'!C6 -> 8 | E26: ='1월'!D6 -> 2 | F26: ='1월'!E6 -> 8-2 | G26: =IFERROR(VLOOKUP($F26,'1월'!$E$4:$H$37,2,0),0) -> 5 | H26: =IFERROR(VLOOKUP($F26,'1월'!$E$4:$H$37,3,0),0) -> 3 | I26: =IFERROR(VLOOKUP($F26,'1월'!$E$4:$H$37,4,0),0) -> 5
A27: ='1월'!A7 -> 2026 | B27: ='1월'!B7 -> 1 | C27: =RIGHT(A27,2)*100+'1월'!B7 -> 2601 | D27: ='1월'!C7 -> 8 | E27: ='1월'!D7 -> 3 | F27: ='1월'!E7 -> 8-3 | G27: =IFERROR(VLOOKUP($F27,'1월'!$E$4:$H$37,2,0),0) -> 5 | H27: =IFERROR(VLOOKUP($F27,'1월'!$E$4:$H$37,3,0),0) -> 3.8 | I27: =IFERROR(VLOOKUP($F27,'1월'!$E$4:$H$37,4,0),0) -> 5
A28: ='1월'!A8 -> 2026 | B28: ='1월'!B8 -> 1 | C28: =RIGHT(A28,2)*100+'1월'!B8 -> 2601 | D28: ='1월'!C8 -> 7 | E28: ='1월'!D8 -> 1 | F28: ='1월'!E8 -> 7-1 | G28: =IFERROR(VLOOKUP($F28,'1월'!$E$4:$H$37,2,0),0) -> 5.1 | H28: =IFERROR(VLOOKUP($F28,'1월'!$E$4:$H$37,3,0),0) -> 3.2 | I28: =IFERROR(VLOOKUP($F28,'1월'!$E$4:$H$37,4,0),0) -> 5.3
A29: ='1월'!A9 -> 2026 | B29: ='1월'!B9 -> 1 | C29: =RIGHT(A29,2)*100+'1월'!B9 -> 2601 | D29: ='1월'!C9 -> 7 | E29: ='1월'!D9 -> 2 | F29: ='1월'!E9 -> 7-2 | G29: =IFERROR(VLOOKUP($F29,'1월'!$E$4:$H$37,2,0),0) -> 5 | H29: =IFERROR(VLOOKUP($F29,'1월'!$E$4:$H$37,3,0),0) -> 3.3 | I29: =IFERROR(VLOOKUP($F29,'1월'!$E$4:$H$37,4,0),0) -> 5.5
A30: ='1월'!A10 -> 2026 | B30: ='1월'!B10 -> 1 | C30: =RIGHT(A30,2)*100+'1월'!B10 -> 2601 | D30: ='1월'!C10 -> 7 | E30: ='1월'!D10 -> 3 | F30: ='1월'!E10 -> 7-3 | G30: =IFERROR(VLOOKUP($F30,'1월'!$E$4:$H$37,2,0),0) -> 5.4 | H30: =IFERROR(VLOOKUP($F30,'1월'!$E$4:$H$37,3,0),0) -> 3.3 | I30: =IFERROR(VLOOKUP($F30,'1월'!$E$4:$H$37,4,0),0) -> 5
A31: ='1월'!A11 -> 2026 | B31: ='1월'!B11 -> 1 | C31: =RIGHT(A31,2)*100+'1월'!B11 -> 2601 | D31: ='1월'!C11 -> 6 | E31: ='1월'!D11 -> 1 | F31: ='1월'!E11 -> 6-1 | G31: =IFERROR(VLOOKUP($F31,'1월'!$E$4:$H$37,2,0),0) -> 6 | H31: =IFERROR(VLOOKUP($F31,'1월'!$E$4:$H$37,3,0),0) -> 3.3 | I31: =IFERROR(VLOOKUP($F31,'1월'!$E$4:$H$37,4,0),0) -> 6.4
A32: ='1월'!A12 -> 2026 | B32: ='1월'!B12 -> 1 | C32: =RIGHT(A32,2)*100+'1월'!B12 -> 2601 | D32: ='1월'!C12 -> 6 | E32: ='1월'!D12 -> 2 | F32: ='1월'!E12 -> 6-2 | G32: =IFERROR(VLOOKUP($F32,'1월'!$E$4:$H$37,2,0),0) -> 6 | H32: =IFERROR(VLOOKUP($F32,'1월'!$E$4:$H$37,3,0),0) -> 3.2 | I32: =IFERROR(VLOOKUP($F32,'1월'!$E$4:$H$37,4,0),0) -> 6
A33: ='1월'!A13 -> 2026 | B33: ='1월'!B13 -> 1 | C33: =RIGHT(A33,2)*100+'1월'!B13 -> 2601 | D33: ='1월'!C13 -> 6 | E33: ='1월'!D13 -> 3 | F33: ='1월'!E13 -> 6-3 | G33: =IFERROR(VLOOKUP($F33,'1월'!$E$4:$H$37,2,0),0) -> 6 | H33: =IFERROR(VLOOKUP($F33,'1월'!$E$4:$H$37,3,0),0) -> 3.2 | I33: =IFERROR(VLOOKUP($F33,'1월'!$E$4:$H$37,4,0),0) -> 6
A34: ='1월'!A14 -> 2026 | B34: ='1월'!B14 -> 1 | C34: =RIGHT(A34,2)*100+'1월'!B14 -> 2601 | D34: ='1월'!C14 -> 5 | E34: ='1월'!D14 -> 1 | F34: ='1월'!E14 -> 5-1 | G34: =IFERROR(VLOOKUP($F34,'1월'!$E$4:$H$37,2,0),0) -> 6.8 | H34: =IFERROR(VLOOKUP($F34,'1월'!$E$4:$H$37,3,0),0) -> 3.5 | I34: =IFERROR(VLOOKUP($F34,'1월'!$E$4:$H$37,4,0),0) -> 6.8
A35: ='1월'!A15 -> 2026 | B35: ='1월'!B15 -> 1 | C35: =RIGHT(A35,2)*100+'1월'!B15 -> 2601 | D35: ='1월'!C15 -> 5 | E35: ='1월'!D15 -> 2 | F35: ='1월'!E15 -> 5-2 | G35: =IFERROR(VLOOKUP($F35,'1월'!$E$4:$H$37,2,0),0) -> 6.5 | H35: =IFERROR(VLOOKUP($F35,'1월'!$E$4:$H$37,3,0),0) -> 3.3 | I35: =IFERROR(VLOOKUP($F35,'1월'!$E$4:$H$37,4,0),0) -> 6.7
... A57: ='1월'!A37 -> 2026 | B57: ='1월'!B37 -> 1 | C57: =RIGHT(A57,2)*100+'1월'!B37 -> 2601 | D57: ='1월'!C37 -> -5 | E57: ='1월'!D37 -> 3 | F57: ='1월'!E37 -> -5-3 | G57: =IFERROR(VLOOKUP($F57,'1월'!$E$4:$H$37,2,0),0) -> 10 | H57: =IFERROR(VLOOKUP($F57,'1월'!$E$4:$H$37,3,0),0) -> 3 | I57: =IFERROR(VLOOKUP($F57,'1월'!$E$4:$H$37,4,0),0) -> 10
A58: ='2월'!A4 -> 2026 | B58: ='2월'!B4 -> 2 | C58: =RIGHT(A58,2)*100+'2월'!B4 -> 2602 | D58: ='2월'!C4 -> 9 | E58: ='2월'!D4 -> 3 | F58: ='2월'!E4 -> 9-3 | G58: =IFERROR(VLOOKUP($F58,'2월'!$E$4:$H$37,2,0),0) -> 5 | H58: =IFERROR(VLOOKUP($F58,'2월'!$E$4:$H$37,3,0),0) -> 3.2 | I58: =IFERROR(VLOOKUP($F58,'2월'!$E$4:$H$37,4,0),0) -> 5
A59: ='2월'!A5 -> 2026 | B59: ='2월'!B5 -> 2 | C59: =RIGHT(A59,2)*100+'2월'!B5 -> 2602 | D59: ='2월'!C5 -> 8 | E59: ='2월'!D5 -> 1 | F59: ='2월'!E5 -> 8-1 | G59: =IFERROR(VLOOKUP($F59,'2월'!$E$4:$H$37,2,0),0) -> 4.8 | H59: =IFERROR(VLOOKUP($F59,'2월'!$E$4:$H$37,3,0),0) -> 3.2 | I59: =IFERROR(VLOOKUP($F59,'2월'!$E$4:$H$37,4,0),0) -> 5
A60: ='2월'!A6 -> 2026 | B60: ='2월'!B6 -> 2 | C60: =RIGHT(A60,2)*100+'2월'!B6 -> 2602 | D60: ='2월'!C6 -> 8 | E60: ='2월'!D6 -> 2 | F60: ='2월'!E6 -> 8-2 | G60: =IFERROR(VLOOKUP($F60,'2월'!$E$4:$H$37,2,0),0) -> 5 | H60: =IFERROR(VLOOKUP($F60,'2월'!$E$4:$H$37,3,0),0) -> 3 | I60: =IFERROR(VLOOKUP($F60,'2월'!$E$4:$H$37,4,0),0) -> 5
A61: ='2월'!A7 -> 2026 | B61: ='2월'!B7 -> 2 | C61: =RIGHT(A61,2)*100+'2월'!B7 -> 2602 | D61: ='2월'!C7 -> 8 | E61: ='2월'!D7 -> 3 | F61: ='2월'!E7 -> 8-3 | G61: =IFERROR(VLOOKUP($F61,'2월'!$E$4:$H$37,2,0),0) -> 5 | H61: =IFERROR(VLOOKUP($F61,'2월'!$E$4:$H$37,3,0),0) -> 3.8 | I61: =IFERROR(VLOOKUP($F61,'2월'!$E$4:$H$37,4,0),0) -> 5
A62: ='2월'!A8 -> 2026 | B62: ='2월'!B8 -> 2 | C62: =RIGHT(A62,2)*100+'2월'!B8 -> 2602 | D62: ='2월'!C8 -> 7 | E62: ='2월'!D8 -> 1 | F62: ='2월'!E8 -> 7-1 | G62: =IFERROR(VLOOKUP($F62,'2월'!$E$4:$H$37,2,0),0) -> 5.1 | H62: =IFERROR(VLOOKUP($F62,'2월'!$E$4:$H$37,3,0),0) -> 3.2 | I62: =IFERROR(VLOOKUP($F62,'2월'!$E$4:$H$37,4,0),0) -> 5.3
A63: ='2월'!A9 -> 2026 | B63: ='2월'!B9 -> 2 | C63: =RIGHT(A63,2)*100+'2월'!B9 -> 2602 | D63: ='2월'!C9 -> 7 | E63: ='2월'!D9 -> 2 | F63: ='2월'!E9 -> 7-2 | G63: =IFERROR(VLOOKUP($F63,'2월'!$E$4:$H$37,2,0),0) -> 5 | H63: =IFERROR(VLOOKUP($F63,'2월'!$E$4:$H$37,3,0),0) -> 3.3 | I63: =IFERROR(VLOOKUP($F63,'2월'!$E$4:$H$37,4,0),0) -> 5.8
A64: ='2월'!A10 -> 2026 | B64: ='2월'!B10 -> 2 | C64: =RIGHT(A64,2)*100+'2월'!B10 -> 2602 | D64: ='2월'!C10 -> 7 | E64: ='2월'!D10 -> 3 | F64: ='2월'!E10 -> 7-3 | G64: =IFERROR(VLOOKUP($F64,'2월'!$E$4:$H$37,2,0),0) -> 5.5 | H64: =IFERROR(VLOOKUP($F64,'2월'!$E$4:$H$37,3,0),0) -> 3.4 | I64: =IFERROR(VLOOKUP($F64,'2월'!$E$4:$H$37,4,0),0) -> 5
A65: ='2월'!A11 -> 2026 | B65: ='2월'!B11 -> 2 | C65: =RIGHT(A65,2)*100+'2월'!B11 -> 2602 | D65: ='2월'!C11 -> 6 | E65: ='2월'!D11 -> 1 | F65: ='2월'!E11 -> 6-1 | G65: =IFERROR(VLOOKUP($F65,'2월'!$E$4:$H$37,2,0),0) -> 6 | H65: =IFERROR(VLOOKUP($F65,'2월'!$E$4:$H$37,3,0),0) -> 3.4 | I65: =IFERROR(VLOOKUP($F65,'2월'!$E$4:$H$37,4,0),0) -> 6.3
A66: ='2월'!A12 -> 2026 | B66: ='2월'!B12 -> 2 | C66: =RIGHT(A66,2)*100+'2월'!B12 -> 2602 | D66: ='2월'!C12 -> 6 | E66: ='2월'!D12 -> 2 | F66: ='2월'!E12 -> 6-2 | G66: =IFERROR(VLOOKUP($F66,'2월'!$E$4:$H$37,2,0),0) -> 6 | H66: =IFERROR(VLOOKUP($F66,'2월'!$E$4:$H$37,3,0),0) -> 3.3 | I66: =IFERROR(VLOOKUP($F66,'2월'!$E$4:$H$37,4,0),0) -> 6
A67: ='2월'!A13 -> 2026 | B67: ='2월'!B13 -> 2 | C67: =RIGHT(A67,2)*100+'2월'!B13 -> 2602 | D67: ='2월'!C13 -> 6 | E67: ='2월'!D13 -> 3 | F67: ='2월'!E13 -> 6-3 | G67: =IFERROR(VLOOKUP($F67,'2월'!$E$4:$H$37,2,0),0) -> 6 | H67: =IFERROR(VLOOKUP($F67,'2월'!$E$4:$H$37,3,0),0) -> 3.2 | I67: =IFERROR(VLOOKUP($F67,'2월'!$E$4:$H$37,4,0),0) -> 6
A68: ='2월'!A14 -> 2026 | B68: ='2월'!B14 -> 2 | C68: =RIGHT(A68,2)*100+'2월'!B14 -> 2602 | D68: ='2월'!C14 -> 5 | E68: ='2월'!D14 -> 1 | F68: ='2월'!E14 -> 5-1 | G68: =IFERROR(VLOOKUP($F68,'2월'!$E$4:$H$37,2,0),0) -> 6.8 | H68: =IFERROR(VLOOKUP($F68,'2월'!$E$4:$H$37,3,0),0) -> 3.5 | I68: =IFERROR(VLOOKUP($F68,'2월'!$E$4:$H$37,4,0),0) -> 6.8
A69: ='2월'!A15 -> 2026 | B69: ='2월'!B15 -> 2 | C69: =RIGHT(A69,2)*100+'2월'!B15 -> 2602 | D69: ='2월'!C15 -> 5 | E69: ='2월'!D15 -> 2 | F69: ='2월'!E15 -> 5-2 | G69: =IFERROR(VLOOKUP($F69,'2월'!$E$4:$H$37,2,0),0) -> 6.6 | H69: =IFERROR(VLOOKUP($F69,'2월'!$E$4:$H$37,3,0),0) -> 3.3 | I69: =IFERROR(VLOOKUP($F69,'2월'!$E$4:$H$37,4,0),0) -> 6.7
... A91: ='2월'!A37 -> 2026 | B91: ='2월'!B37 -> 2 | C91: =RIGHT(A91,2)*100+'2월'!B37 -> 2602 | D91: ='2월'!C37 -> -5 | E91: ='2월'!D37 -> 3 | F91: ='2월'!E37 -> -5-3 | G91: =IFERROR(VLOOKUP($F91,'2월'!$E$4:$H$37,2,0),0) -> 10 | H91: =IFERROR(VLOOKUP($F91,'2월'!$E$4:$H$37,3,0),0) -> 3 | I91: =IFERROR(VLOOKUP($F91,'2월'!$E$4:$H$37,4,0),0) -> 10.1
A92: ='3월'!A4 -> 2025 | B92: ='3월'!B4 -> 3 | C92: =RIGHT(A92,2)*100+'3월'!B4 -> 2503 | D92: ='3월'!C4 -> 9 | E92: ='3월'!D4 -> 3 | F92: ='3월'!E4 -> 9-3 | G92: =IFERROR(VLOOKUP($F92,'3월'!$E$4:$H$37,2,0),0) -> 5 | H92: =IFERROR(VLOOKUP($F92,'3월'!$E$4:$H$37,3,0),0) -> 3.2 | I92: =IFERROR(VLOOKUP($F92,'3월'!$E$4:$H$37,4,0),0) -> 4.9
A93: ='3월'!A5 -> 2025 | B93: ='3월'!B5 -> 3 | C93: =RIGHT(A93,2)*100+'3월'!B5 -> 2503 | D93: ='3월'!C5 -> 8 | E93: ='3월'!D5 -> 1 | F93: ='3월'!E5 -> 8-1 | G93: =IFERROR(VLOOKUP($F93,'3월'!$E$4:$H$37,2,0),0) -> 4.8 | H93: =IFERROR(VLOOKUP($F93,'3월'!$E$4:$H$37,3,0),0) -> 3.1 | I93: =IFERROR(VLOOKUP($F93,'3월'!$E$4:$H$37,4,0),0) -> 5
A94: ='3월'!A6 -> 2025 | B94: ='3월'!B6 -> 3 | C94: =RIGHT(A94,2)*100+'3월'!B6 -> 2503 | D94: ='3월'!C6 -> 8 | E94: ='3월'!D6 -> 2 | F94: ='3월'!E6 -> 8-2 | G94: =IFERROR(VLOOKUP($F94,'3월'!$E$4:$H$37,2,0),0) -> 5 | H94: =IFERROR(VLOOKUP($F94,'3월'!$E$4:$H$37,3,0),0) -> 3 | I94: =IFERROR(VLOOKUP($F94,'3월'!$E$4:$H$37,4,0),0) -> 5
A95: ='3월'!A7 -> 2025 | B95: ='3월'!B7 -> 3 | C95: =RIGHT(A95,2)*100+'3월'!B7 -> 2503 | D95: ='3월'!C7 -> 8 | E95: ='3월'!D7 -> 3 | F95: ='3월'!E7 -> 8-3 | G95: =IFERROR(VLOOKUP($F95,'3월'!$E$4:$H$37,2,0),0) -> 5 | H95: =IFERROR(VLOOKUP($F95,'3월'!$E$4:$H$37,3,0),0) -> 3.8 | I95: =IFERROR(VLOOKUP($F95,'3월'!$E$4:$H$37,4,0),0) -> 5
A96: ='3월'!A8 -> 2025 | B96: ='3월'!B8 -> 3 | C96: =RIGHT(A96,2)*100+'3월'!B8 -> 2503 | D96: ='3월'!C8 -> 7 | E96: ='3월'!D8 -> 1 | F96: ='3월'!E8 -> 7-1 | G96: =IFERROR(VLOOKUP($F96,'3월'!$E$4:$H$37,2,0),0) -> 5.2 | H96: =IFERROR(VLOOKUP($F96,'3월'!$E$4:$H$37,3,0),0) -> 3.3 | I96: =IFERROR(VLOOKUP($F96,'3월'!$E$4:$H$37,4,0),0) -> 5.4
A97: ='3월'!A9 -> 2025 | B97: ='3월'!B9 -> 3 | C97: =RIGHT(A97,2)*100+'3월'!B9 -> 2503 | D97: ='3월'!C9 -> 7 | E97: ='3월'!D9 -> 2 | F97: ='3월'!E9 -> 7-2 | G97: =IFERROR(VLOOKUP($F97,'3월'!$E$4:$H$37,2,0),0) -> 5 | H97: =IFERROR(VLOOKUP($F97,'3월'!$E$4:$H$37,3,0),0) -> 3.3 | I97: =IFERROR(VLOOKUP($F97,'3월'!$E$4:$H$37,4,0),0) -> 5.8
A98: ='3월'!A10 -> 2025 | B98: ='3월'!B10 -> 3 | C98: =RIGHT(A98,2)*100+'3월'!B10 -> 2503 | D98: ='3월'!C10 -> 7 | E98: ='3월'!D10 -> 3 | F98: ='3월'!E10 -> 7-3 | G98: =IFERROR(VLOOKUP($F98,'3월'!$E$4:$H$37,2,0),0) -> 5.6 | H98: =IFERROR(VLOOKUP($F98,'3월'!$E$4:$H$37,3,0),0) -> 3.5 | I98: =IFERROR(VLOOKUP($F98,'3월'!$E$4:$H$37,4,0),0) -> 5
A99: ='3월'!A11 -> 2025 | B99: ='3월'!B11 -> 3 | C99: =RIGHT(A99,2)*100+'3월'!B11 -> 2503 | D99: ='3월'!C11 -> 6 | E99: ='3월'!D11 -> 1 | F99: ='3월'!E11 -> 6-1 | G99: =IFERROR(VLOOKUP($F99,'3월'!$E$4:$H$37,2,0),0) -> 6.1 | H99: =IFERROR(VLOOKUP($F99,'3월'!$E$4:$H$37,3,0),0) -> 3.4 | I99: =IFERROR(VLOOKUP($F99,'3월'!$E$4:$H$37,4,0),0) -> 6.5
A100: ='3월'!A12 -> 2025 | B100: ='3월'!B12 -> 3 | C100: =RIGHT(A100,2)*100+'3월'!B12 -> 2503 | D100: ='3월'!C12 -> 6 | E100: ='3월'!D12 -> 2 | F100: ='3월'!E12 -> 6-2 | G100: =IFERROR(VLOOKUP($F100,'3월'!$E$4:$H$37,2,0),0) -> 6 | H100: =IFERROR(VLOOKUP($F100,'3월'!$E$4:$H$37,3,0),0) -> 3.4 | I100: =IFERROR(VLOOKUP($F100,'3월'!$E$4:$H$37,4,0),0) -> 6
A101: ='3월'!A13 -> 2025 | B101: ='3월'!B13 -> 3 | C101: =RIGHT(A101,2)*100+'3월'!B13 -> 2503 | D101: ='3월'!C13 -> 6 | E101: ='3월'!D13 -> 3 | F101: ='3월'!E13 -> 6-3 | G101: =IFERROR(VLOOKUP($F101,'3월'!$E$4:$H$37,2,0),0) -> 6.1 | H101: =IFERROR(VLOOKUP($F101,'3월'!$E$4:$H$37,3,0),0) -> 3.3 | I101: =IFERROR(VLOOKUP($F101,'3월'!$E$4:$H$37,4,0),0) -> 6
...

Sheet (년말) DIV 압력 Trend 생성
A1: =AE1&"년" -> 년 | C1: 8-1층 | E1: 8층 | G1: 7층 | I1: 6층 | K1: 5층 | M1: 3층 | O1: 2층 | Q1: 1층 | S1: B1층 | U1: B2층 | W1: B3층 | Y1: B4층 | AA1: B5층 | AF1: 1. 연도 선택 후, 마우스 우클릭, 새로고침하여 좌측 트랜드 업데이트. | AO1: 3. 매년 12월이 끝나기 전, 트렌드 영역 선택 후 복사.
AF2: 2. 밑에 회색 영역은 신경쓰지 말 것. | AO2: 4. 해당 년도 시트 생성 > 첫번째 셀에서 마우스 우클릭 >선택하여 붙여넣기 > 기타 붙여넣기 옵션 > 그림
A3: DIV #1 연구동 서 편 / 주차장 기계실 | B3: 1차압 | AG3: 위치 | AH3: 값
AG4: 1 | AJ4: 2 | AM4: 3
AD5: 층 | AE5: 년월 | AF5: 월 | AG5: 1차압 | AH5: 2차압 | AI5: 챔버압 | AJ5: 1차압 | AK5: 2차압 | AL5: 챔버압 | AM5: 1차압 | AN5: 2차압 | AO5: 챔버압
AD6: 9 | AE6: 2502 | AF6: 2 | AM6: 4.9 | AN6: 3.2 | AO6: 4.8
AE7: 2503 | AF7: 3 | AM7: 5 | AN7: 3.2 | AO7: 4.9
B8: 2차압 | AE8: 2504 | AF8: 4 | AM8: 5 | AN8: 3.2 | AO8: 4.9
AE9: 2505 | AF9: 5 | AM9: 5 | AN9: 3.2 | AO9: 5
AE10: 2506 | AF10: 6 | AM10: 5 | AN10: 3.1 | AO10: 4.9
AE11: 2507 | AF11: 7 | AM11: 5 | AN11: 3 | AO11: 4.9
AE12: 2508 | AF12: 8 | AM12: 5 | AN12: 3 | AO12: 5
B13: 챔버압 | AE13: 2509 | AF13: 9 | AM13: 5 | AN13: 3 | AO13: 4.9
AE14: 2510 | AF14: 10 | AM14: 4.9 | AN14: 3 | AO14: 4.7
AE15: 2511 | AF15: 11 | AM15: 5 | AN15: 3.1 | AO15: 4.9
AE16: 2512 | AF16: 12 | AM16: 5 | AN16: 3.1 | AO16: 4.9
AE17: 2601 | AF17: 1 | AM17: 4.9 | AN17: 3.2 | AO17: 4.7
A18: DIV #2 연구동 동 편 / 주차장 팬룸 1 | B18: 1차압 | AD18: 8 | AE18: 2502 | AF18: 2 | AG18: 4.6 | AH18: 3.2 | AI18: 5 | AJ18: 5 | AK18: 3 | AL18: 5 | AM18: 5 | AN18: 3.8 | AO18: 5
AE19: 2503 | AF19: 3 | AG19: 4.8 | AH19: 3.1 | AI19: 5 | AJ19: 5 | AK19: 3 | AL19: 5 | AM19: 5 | AN19: 3.8 | AO19: 5
AE20: 2504 | AF20: 4 | AG20: 4.8 | AH20: 3.1 | AI20: 5 | AJ20: 5 | AK20: 3 | AL20: 5 | AM20: 5 | AN20: 3.8 | AO20: 5
AE21: 2505 | AF21: 5 | AG21: 4.8 | AH21: 3 | AI21: 5 | AJ21: 5 | AK21: 3 | AL21: 5 | AM21: 5 | AN21: 3.8 | AO21: 5
AE22: 2506 | AF22: 6 | AG22: 4.9 | AH22: 3 | AI22: 5 | AJ22: 5 | AK22: 3 | AL22: 5 | AM22: 5 | AN22: 3.8 | AO22: 5
B23: 2차압 | AE23: 2507 | AF23: 7 | AG23: 4.9 | AH23: 3.1 | AI23: 5.1 | AJ23: 5 | AK23: 3 | AL23: 5 | AM23: 5 | AN23: 3.8 | AO23: 5
AE24: 2508 | AF24: 8 | AG24: 4.9 | AH24: 3.5 | AI24: 5 | AJ24: 5 | AK24: 3 | AL24: 5 | AM24: 5 | AN24: 3.8 | AO24: 5
AE25: 2509 | AF25: 9 | AG25: 4.8 | AH25: 3.3 | AI25: 5 | AJ25: 5 | AK25: 3 | AL25: 5 | AM25: 5 | AN25: 3.8 | AO25: 5
AE26: 2510 | AF26: 10 | AG26: 4.8 | AH26: 3.2 | AI26: 5 | AJ26: 5 | AK26: 3 | AL26: 5 | AM26: 5 | AN26: 3.8 | AO26: 5
AE27: 2511 | AF27: 11 | AG27: 5 | AH27: 3.1 | AI27: 5 | AJ27: 5 | AK27: 3 | AL27: 5 | AM27: 5 | AN27: 3.8 | AO27: 5
B28: 챔버압 | AE28: 2512 | AF28: 12 | AG28: 5 | AH28: 3.1 | AI28: 5 | AJ28: 5 | AK28: 3 | AL28: 5 | AM28: 5 | AN28: 3.8 | AO28: 5
AE29: 2601 | AF29: 1 | AG29: 4.6 | AH29: 3.2 | AI29: 5 | AJ29: 5 | AK29: 3 | AL29: 5 | AM29: 5 | AN29: 3.8 | AO29: 5
AD30: 7 | AE30: 2502 | AF30: 2 | AG30: 5.1 | AH30: 3.3 | AI30: 5.2 | AJ30: 5 | AK30: 3.3 | AL30: 5.5 | AM30: 5.4 | AN30: 3.4 | AO30: 5
AE31: 2503 | AF31: 3 | AG31: 5.2 | AH31: 3.3 | AI31: 5.4 | AJ31: 5 | AK31: 3.3 | AL31: 5.8 | AM31: 5.6 | AN31: 3.5 | AO31: 5
AE32: 2504 | AF32: 4 | AG32: 5.1 | AH32: 3.2 | AI32: 5.4 | AJ32: 5 | AK32: 3.3 | AL32: 5.8 | AM32: 5.7 | AN32: 3.5 | AO32: 5
A33: DIV #3 사무동 서 편 / 주차장 팬룸 2 | B33: 1차압 | AE33: 2505 | AF33: 5 | AG33: 5.3 | AH33: 3.1 | AI33: 5.5 | AJ33: 5.1 | AK33: 3.3 | AL33: 5.8 | AM33: 5.6 | AN33: 3.5 | AO33: 5
AE34: 2506 | AF34: 6 | AG34: 5.2 | AH34: 3 | AI34: 5.5 | AJ34: 5.2 | AK34: 3.3 | AL34: 5.8 | AM34: 5.5 | AN34: 3.4 | AO34: 5
AE35: 2507 | AF35: 7 | AG35: 5.1 | AH35: 3 | AI35: 5.4 | AJ35: 5.1 | AK35: 3.3 | AL35: 5.9 | AM35: 5.8 | AN35: 3.4 | AO35: 5.1
AE36: 2508 | AF36: 8 | AG36: 5.3 | AH36: 3 | AI36: 5.5 | AJ36: 5.1 | AK36: 3.3 | AL36: 5.9 | AM36: 5.9 | AN36: 3.3 | AO36: 5.1
AE37: 2509 | AF37: 9 | AG37: 5.2 | AH37: 2.9 | AI37: 5.5 | AJ37: 5.2 | AK37: 3.2 | AL37: 5.7 | AM37: 5.7 | AN37: 3.3 | AO37: 5.1
B38: 2차압 | AE38: 2510 | AF38: 10 | AG38: 5.1 | AH38: 2.9 | AI38: 5.4 | AJ38: 5 | AK38: 3.2 | AL38: 5.8 | AM38: 5.5 | AN38: 3.3 | AO38: 5
AE39: 2511 | AF39: 11 | AG39: 5.1 | AH39: 3.2 | AI39: 5.5 | AJ39: 5.1 | AK39: 3.2 | AL39: 5.8 | AM39: 5.8 | AN39: 3.4 | AO39: 5.1
AE40: 2512 | AF40: 12 | AG40: 5.2 | AH40: 3.3 | AI40: 5.4 | AJ40: 5.1 | AK40: 3.3 | AL40: 5.8 | AM40: 5.6 | AN40: 3.4 | AO40: 5
...

Sheet 참고.DIV 배수 주기
A1: 1 | B1: 2 | C1: 3 | D1: 4 | E1: 5 | F1: 6 | G1: 7 | H1: 8 | I1: 9 | J1: 10 | K1: 11 | L1: 12 | M1: 13 | N1: 14 | O1: 15 | P1: 16 | Q1: 17 | R1: 18 | S1: 19 | T1: 20 | U1: 21 | V1: 22 | W1: 23 | X1: 24 | Y1: 25 | Z1: 26 | AA1: 27 | AB1: 28 | AC1: 29 | AD1: 30 | AE1: 31 | AF1: 32 | AG1: 33 | AH1: 34 | AI1: 35 | AJ1: 36 | AK1: 37 | AL1: 38 | AM1: 39 | AN1: 40 | AO1: 41 | AP1: 42 | AQ1: 43 | AR1: 44 | AS1: 45 | AT1: 46 | AU1: 47 | AV1: 48 | AW1: 49 | AX1: 50 | AY1: 51 | AZ1: 52 | BA1: 53 | BB1: 54 | BC1: 55 | BD1: 56 | BE1: 57 | BF1: 58 | BG1: 59 | BH1: 60 | BI1: 61 | BJ1: 62 | BK1: 63 | BL1: 64 | BM1: 65 | BN1: 66 | BO1: 67 | BP1: 68 | BQ1: 69
A2: 배수 | B2: 8층 | J2: 7층 | P2: 6층 | V2: 5층 | AB2: 3층 | AH2: 2층 | AL2: 1층 | AR2: B1층 | AX2: B2층 | BD2: B3층 | BH2: B4층 | BN2: B5층
B3: 계단 위 | D3: 연구동 | H3: 사무동 | J3: 연구동 | N3: 사무동 | P3: 연구동 | T3: 사무동 | V3: 연구동 | Z3: 사무동 | AB3: 연구동 | AF3: 사무동 | AH3: 연구동 | AJ3: 사무동 | AL3: 연구동 | AP3: 사무동
B4: PS실 | D4: 공조실 | F4: PS실 | H4: PS실 | J4: 공조실 | L4: PS실 | N4: PS실 | P4: 공조실 | R4: PS실 | T4: PS실 | V4: 공조실 | X4: PS실 | Z4: PS실 | AB4: 공조실 | AD4: PS실 | AF4: PS실 | AH4: PS실 | AJ4: PS실 | AL4: 공조실 | AN4: PS실 | AP4: PS실 | AR4: 공조실 | AT4: 식당 | AV4: 화장실 | AX4: 공조실 | AZ4: CPX실 | BB4: PS실 | BD4: 휀룸1 | BF4: 기사대기실 | BH4: 휀룸1 | BJ4: 기계실 | BL4: 창고 | BN4: 휀룸1 | BP4: 휀룸2
A5: 트렌드
A6: 이번 주기 | B6: =IF(IF(C7=0,0,C6-C7)<=0,0,IF(C7=0,0,C6-C7)) -> 0 | C6: =VLOOKUP($A14,$A$14:$BQ$25,C$1,0) -> 0 | D6: =IF(IF(E7=0,0,E6-E7)<=0,0,IF(E7=0,0,E6-E7)) -> 0 | E6: =VLOOKUP($A14,$A$14:$BQ$25,E$1,0) -> 0 | F6: =IF(IF(G7=0,0,G6-G7)<=0,0,IF(G7=0,0,G6-G7)) -> 0 | G6: =VLOOKUP($A14,$A$14:$BQ$25,G$1,0) -> 0 | H6: =IF(IF(I7=0,0,I6-I7)<=0,0,IF(I7=0,0,I6-I7)) -> 0 | I6: =VLOOKUP($A14,$A$14:$BQ$25,I$1,0) -> 0 | J6: =IF(IF(K7=0,0,K6-K7)<=0,0,IF(K7=0,0,K6-K7)) -> 0 | K6: =VLOOKUP($A14,$A$14:$BQ$25,K$1,0) -> 0 | L6: =IF(IF(M7=0,0,M6-M7)<=0,0,IF(M7=0,0,M6-M7)) -> 0 | M6: =VLOOKUP($A14,$A$14:$BQ$25,M$1,0) -> 0 | N6: =IF(IF(O7=0,0,O6-O7)<=0,0,IF(O7=0,0,O6-O7)) -> 0 | O6: =VLOOKUP($A14,$A$14:$BQ$25,O$1,0) -> 45876 | P6: =IF(IF(Q7=0,0,Q6-Q7)<=0,0,IF(Q7=0,0,Q6-Q7)) -> 0 | Q6: =VLOOKUP($A14,$A$14:$BQ$25,Q$1,0) -> 0 | R6: =IF(IF(S7=0,0,S6-S7)<=0,0,IF(S7=0,0,S6-S7)) -> 0 | S6: =VLOOKUP($A14,$A$14:$BQ$25,S$1,0) -> 0 | T6: =IF(IF(U7=0,0,U6-U7)<=0,0,IF(U7=0,0,U6-U7)) -> 0 | U6: =VLOOKUP($A14,$A$14:$BQ$25,U$1,0) -> 0 | V6: =IF(IF(W7=0,0,W6-W7)<=0,0,IF(W7=0,0,W6-W7)) -> 0 | W6: =VLOOKUP($A14,$A$14:$BQ$25,W$1,0) -> 0 | X6: =IF(IF(Y7=0,0,Y6-Y7)<=0,0,IF(Y7=0,0,Y6-Y7)) -> 0 | Y6: =VLOOKUP($A14,$A$14:$BQ$25,Y$1,0) -> 0 | Z6: =IF(IF(AA7=0,0,AA6-AA7)<=0,0,IF(AA7=0,0,AA6-AA7)) -> 0 | AA6: =VLOOKUP($A14,$A$14:$BQ$25,AA$1,0) -> 0 | AB6: =IF(IF(AC7=0,0,AC6-AC7)<=0,0,IF(AC7=0,0,AC6-AC7)) -> 0 | AC6: =VLOOKUP($A14,$A$14:$BQ$25,AC$1,0) -> 0 | AD6: =IF(IF(AE7=0,0,AE6-AE7)<=0,0,IF(AE7=0,0,AE6-AE7)) -> 0 | AE6: =VLOOKUP($A14,$A$14:$BQ$25,AE$1,0) -> 0 | AF6: =IF(IF(AG7=0,0,AG6-AG7)<=0,0,IF(AG7=0,0,AG6-AG7)) -> 0 | AG6: =VLOOKUP($A14,$A$14:$BQ$25,AG$1,0) -> 0 | AH6: =IF(IF(AI7=0,0,AI6-AI7)<=0,0,IF(AI7=0,0,AI6-AI7)) -> 272 | AI6: =VLOOKUP($A14,$A$14:$BQ$25,AI$1,0) -> 45784 | AJ6: =IF(IF(AK7=0,0,AK6-AK7)<=0,0,IF(AK7=0,0,AK6-AK7)) -> 0 | AK6: =VLOOKUP($A14,$A$14:$BQ$25,AK$1,0) -> 0 | AL6: =IF(IF(AM7=0,0,AM6-AM7)<=0,0,IF(AM7=0,0,AM6-AM7)) -> 0 | AM6: =VLOOKUP($A14,$A$14:$BQ$25,AM$1,0) -> 0 | AN6: =IF(IF(AO7=0,0,AO6-AO7)<=0,0,IF(AO7=0,0,AO6-AO7)) -> 0 | AO6: =VLOOKUP($A14,$A$14:$BQ$25,AO$1,0) -> 0 | AP6: =IF(IF(AQ7=0,0,AQ6-AQ7)<=0,0,IF(AQ7=0,0,AQ6-AQ7)) -> 0 | AQ6: =VLOOKUP($A14,$A$14:$BQ$25,AQ$1,0) -> 0 | AR6: =IF(IF(AS7=0,0,AS6-AS7)<=0,0,IF(AS7=0,0,AS6-AS7)) -> 0 | AS6: =VLOOKUP($A14,$A$14:$BQ$25,AS$1,0) -> 0 | AT6: =IF(IF(AU7=0,0,AU6-AU7)<=0,0,IF(AU7=0,0,AU6-AU7)) -> 0 | AU6: =VLOOKUP($A14,$A$14:$BQ$25,AU$1,0) -> 0 | AV6: =IF(IF(AW7=0,0,AW6-AW7)<=0,0,IF(AW7=0,0,AW6-AW7)) -> 0 | AW6: =VLOOKUP($A14,$A$14:$BQ$25,AW$1,0) -> 0 | AX6: =IF(IF(AY7=0,0,AY6-AY7)<=0,0,IF(AY7=0,0,AY6-AY7)) -> 0 | AY6: =VLOOKUP($A14,$A$14:$BQ$25,AY$1,0) -> 0 | AZ6: =IF(IF(BA7=0,0,BA6-BA7)<=0,0,IF(BA7=0,0,BA6-BA7)) -> 291 | BA6: =VLOOKUP($A14,$A$14:$BQ$25,BA$1,0) -> 45663 | BB6: =IF(IF(BC7=0,0,BC6-BC7)<=0,0,IF(BC7=0,0,BC6-BC7)) -> 0 | BC6: =VLOOKUP($A14,$A$14:$BQ$25,BC$1,0) -> 0 | BD6: =IF(IF(BE7=0,0,BE6-BE7)<=0,0,IF(BE7=0,0,BE6-BE7)) -> 0 | BE6: =VLOOKUP($A14,$A$14:$BQ$25,BE$1,0) -> 0 | BF6: =IF(IF(BG7=0,0,BG6-BG7)<=0,0,IF(BG7=0,0,BG6-BG7)) -> 0 | BG6: =VLOOKUP($A14,$A$14:$BQ$25,BG$1,0) -> 0 | BH6: =IF(IF(BI7=0,0,BI6-BI7)<=0,0,IF(BI7=0,0,BI6-BI7)) -> 0 | BI6: =VLOOKUP($A14,$A$14:$BQ$25,BI$1,0) -> 0 | BJ6: =IF(IF(BK7=0,0,BK6-BK7)<=0,0,IF(BK7=0,0,BK6-BK7)) -> 391 | BK6: =VLOOKUP($A14,$A$14:$BQ$25,BK$1,0) -> 45904 | BL6: =IF(IF(BM7=0,0,BM6-BM7)<=0,0,IF(BM7=0,0,BM6-BM7)) -> 0 | BM6: =VLOOKUP($A14,$A$14:$BQ$25,BM$1,0) -> 0 | BN6: =IF(IF(BO7=0,0,BO6-BO7)<=0,0,IF(BO7=0,0,BO6-BO7)) -> 46 | BO6: =VLOOKUP($A14,$A$14:$BQ$25,BO$1,0) -> 45958 | BP6: =IF(IF(BQ7=0,0,BQ6-BQ7)<=0,0,IF(BQ7=0,0,BQ6-BQ7)) -> 30 | BQ6: =VLOOKUP($A14,$A$14:$BQ$25,BQ$1,0) -> 45330
A7: 지난 주기 | B7: =IF(IF(C8=0,0,C7-C8)<=0,0,IF(C8=0,0,C7-C8)) -> 0 | C7: =VLOOKUP($A15,$A$14:$BQ$25,C$1,0) -> 0 | D7: =IF(IF(E8=0,0,E7-E8)<=0,0,IF(E8=0,0,E7-E8)) -> 0 | E7: =VLOOKUP($A15,$A$14:$BQ$25,E$1,0) -> 0 | F7: =IF(IF(G8=0,0,G7-G8)<=0,0,IF(G8=0,0,G7-G8)) -> 0 | G7: =VLOOKUP($A15,$A$14:$BQ$25,G$1,0) -> 0 | H7: =IF(IF(I8=0,0,I7-I8)<=0,0,IF(I8=0,0,I7-I8)) -> 0 | I7: =VLOOKUP($A15,$A$14:$BQ$25,I$1,0) -> 0 | J7: =IF(IF(K8=0,0,K7-K8)<=0,0,IF(K8=0,0,K7-K8)) -> 0 | K7: =VLOOKUP($A15,$A$14:$BQ$25,K$1,0) -> 0 | L7: =IF(IF(M8=0,0,M7-M8)<=0,0,IF(M8=0,0,M7-M8)) -> 0 | M7: =VLOOKUP($A15,$A$14:$BQ$25,M$1,0) -> 0 | N7: =IF(IF(O8=0,0,O7-O8)<=0,0,IF(O8=0,0,O7-O8)) -> 0 | O7: =VLOOKUP($A15,$A$14:$BQ$25,O$1,0) -> 0 | P7: =IF(IF(Q8=0,0,Q7-Q8)<=0,0,IF(Q8=0,0,Q7-Q8)) -> 0 | Q7: =VLOOKUP($A15,$A$14:$BQ$25,Q$1,0) -> 0 | R7: =IF(IF(S8=0,0,S7-S8)<=0,0,IF(S8=0,0,S7-S8)) -> 0 | S7: =VLOOKUP($A15,$A$14:$BQ$25,S$1,0) -> 0 | T7: =IF(IF(U8=0,0,U7-U8)<=0,0,IF(U8=0,0,U7-U8)) -> 0 | U7: =VLOOKUP($A15,$A$14:$BQ$25,U$1,0) -> 0 | V7: =IF(IF(W8=0,0,W7-W8)<=0,0,IF(W8=0,0,W7-W8)) -> 0 | W7: =VLOOKUP($A15,$A$14:$BQ$25,W$1,0) -> 0 | X7: =IF(IF(Y8=0,0,Y7-Y8)<=0,0,IF(Y8=0,0,Y7-Y8)) -> 0 | Y7: =VLOOKUP($A15,$A$14:$BQ$25,Y$1,0) -> 0 | Z7: =IF(IF(AA8=0,0,AA7-AA8)<=0,0,IF(AA8=0,0,AA7-AA8)) -> 0 | AA7: =VLOOKUP($A15,$A$14:$BQ$25,AA$1,0) -> 0 | AB7: =IF(IF(AC8=0,0,AC7-AC8)<=0,0,IF(AC8=0,0,AC7-AC8)) -> 0 | AC7: =VLOOKUP($A15,$A$14:$BQ$25,AC$1,0) -> 0 | AD7: =IF(IF(AE8=0,0,AE7-AE8)<=0,0,IF(AE8=0,0,AE7-AE8)) -> 0 | AE7: =VLOOKUP($A15,$A$14:$BQ$25,AE$1,0) -> 0 | AF7: =IF(IF(AG8=0,0,AG7-AG8)<=0,0,IF(AG8=0,0,AG7-AG8)) -> 0 | AG7: =VLOOKUP($A15,$A$14:$BQ$25,AG$1,0) -> 0 | AH7: =IF(IF(AI8=0,0,AI7-AI8)<=0,0,IF(AI8=0,0,AI7-AI8)) -> 140 | AI7: =VLOOKUP($A15,$A$14:$BQ$25,AI$1,0) -> 45512 | AJ7: =IF(IF(AK8=0,0,AK7-AK8)<=0,0,IF(AK8=0,0,AK7-AK8)) -> 0 | AK7: =VLOOKUP($A15,$A$14:$BQ$25,AK$1,0) -> 0 | AL7: =IF(IF(AM8=0,0,AM7-AM8)<=0,0,IF(AM8=0,0,AM7-AM8)) -> 0 | AM7: =VLOOKUP($A15,$A$14:$BQ$25,AM$1,0) -> 0 | AN7: =IF(IF(AO8=0,0,AO7-AO8)<=0,0,IF(AO8=0,0,AO7-AO8)) -> 0 | AO7: =VLOOKUP($A15,$A$14:$BQ$25,AO$1,0) -> 0 | AP7: =IF(IF(AQ8=0,0,AQ7-AQ8)<=0,0,IF(AQ8=0,0,AQ7-AQ8)) -> 0 | AQ7: =VLOOKUP($A15,$A$14:$BQ$25,AQ$1,0) -> 0 | AR7: =IF(AS8=0,0,AS7-AS8) -> 0 | AS7: =VLOOKUP($A15,$A$14:$BQ$25,AS$1,0) -> 0 | AT7: =IF(IF(AU8=0,0,AU7-AU8)<=0,0,IF(AU8=0,0,AU7-AU8)) -> 0 | AU7: =VLOOKUP($A15,$A$14:$BQ$25,AU$1,0) -> 0 | AV7: =IF(IF(AW8=0,0,AW7-AW8)<=0,0,IF(AW8=0,0,AW7-AW8)) -> 0 | AW7: =VLOOKUP($A15,$A$14:$BQ$25,AW$1,0) -> 0 | AX7: =IF(IF(AY8=0,0,AY7-AY8)<=0,0,IF(AY8=0,0,AY7-AY8)) -> 0 | AY7: =VLOOKUP($A15,$A$14:$BQ$25,AY$1,0) -> 0 | AZ7: =IF(IF(BA8=0,0,BA7-BA8)<=0,0,IF(BA8=0,0,BA7-BA8)) -> 42 | BA7: =VLOOKUP($A15,$A$14:$BQ$25,BA$1,0) -> 45372 | BB7: =IF(IF(BC8=0,0,BC7-BC8)<=0,0,IF(BC8=0,0,BC7-BC8)) -> 0 | BC7: =VLOOKUP($A15,$A$14:$BQ$25,BC$1,0) -> 0 | BD7: =IF(IF(BE8=0,0,BE7-BE8)<=0,0,IF(BE8=0,0,BE7-BE8)) -> 0 | BE7: =VLOOKUP($A15,$A$14:$BQ$25,BE$1,0) -> 0 | BF7: =IF(IF(BG8=0,0,BG7-BG8)<=0,0,IF(BG8=0,0,BG7-BG8)) -> 0 | BG7: =VLOOKUP($A15,$A$14:$BQ$25,BG$1,0) -> 0 | BH7: =IF(IF(BI8=0,0,BI7-BI8)<=0,0,IF(BI8=0,0,BI7-BI8)) -> 0 | BI7: =VLOOKUP($A15,$A$14:$BQ$25,BI$1,0) -> 0 | BJ7: =IF(IF(BK8=0,0,BK7-BK8)<=0,0,IF(BK8=0,0,BK7-BK8)) -> 87 | BK7: =VLOOKUP($A15,$A$14:$BQ$25,BK$1,0) -> 45513 | BL7: =IF(IF(BM8=0,0,BM7-BM8)<=0,0,IF(BM8=0,0,BM7-BM8)) -> 0 | BM7: =VLOOKUP($A15,$A$14:$BQ$25,BM$1,0) -> 0 | BN7: =IF(IF(BO8=0,0,BO7-BO8)<=0,0,IF(BO8=0,0,BO7-BO8)) -> 189 | BO7: =VLOOKUP($A15,$A$14:$BQ$25,BO$1,0) -> 45912 | BP7: =IF(IF(BQ8=0,0,BQ7-BQ8)<=0,0,IF(BQ8=0,0,BQ7-BQ8)) -> 0 | BQ7: =VLOOKUP($A15,$A$14:$BQ$25,BQ$1,0) -> 45300
B8: =IF(IF(C9=0,0,C8-C9)<=0,0,IF(C9=0,0,C8-C9)) -> 0 | C8: =VLOOKUP($A16,$A$14:$BQ$25,C$1,0) -> 0 | D8: =IF(IF(E9=0,0,E8-E9)<=0,0,IF(E9=0,0,E8-E9)) -> 0 | E8: =VLOOKUP($A16,$A$14:$BQ$25,E$1,0) -> 0 | F8: =IF(IF(G9=0,0,G8-G9)<=0,0,IF(G9=0,0,G8-G9)) -> 0 | G8: =VLOOKUP($A16,$A$14:$BQ$25,G$1,0) -> 0 | H8: =IF(IF(I9=0,0,I8-I9)<=0,0,IF(I9=0,0,I8-I9)) -> 0 | I8: =VLOOKUP($A16,$A$14:$BQ$25,I$1,0) -> 0 | J8: =IF(IF(K9=0,0,K8-K9)<=0,0,IF(K9=0,0,K8-K9)) -> 0 | K8: =VLOOKUP($A16,$A$14:$BQ$25,K$1,0) -> 0 | L8: =IF(IF(M9=0,0,M8-M9)<=0,0,IF(M9=0,0,M8-M9)) -> 0 | M8: =VLOOKUP($A16,$A$14:$BQ$25,M$1,0) -> 0 | N8: =IF(IF(O9=0,0,O8-O9)<=0,0,IF(O9=0,0,O8-O9)) -> 0 | O8: =VLOOKUP($A16,$A$14:$BQ$25,O$1,0) -> 0 | P8: =IF(IF(Q9=0,0,Q8-Q9)<=0,0,IF(Q9=0,0,Q8-Q9)) -> 0 | Q8: =VLOOKUP($A16,$A$14:$BQ$25,Q$1,0) -> 0 | R8: =IF(IF(S9=0,0,S8-S9)<=0,0,IF(S9=0,0,S8-S9)) -> 0 | S8: =VLOOKUP($A16,$A$14:$BQ$25,S$1,0) -> 0 | T8: =IF(IF(U9=0,0,U8-U9)<=0,0,IF(U9=0,0,U8-U9)) -> 0 | U8: =VLOOKUP($A16,$A$14:$BQ$25,U$1,0) -> 0 | V8: =IF(IF(W9=0,0,W8-W9)<=0,0,IF(W9=0,0,W8-W9)) -> 0 | W8: =VLOOKUP($A16,$A$14:$BQ$25,W$1,0) -> 0 | X8: =IF(IF(Y9=0,0,Y8-Y9)<=0,0,IF(Y9=0,0,Y8-Y9)) -> 0 | Y8: =VLOOKUP($A16,$A$14:$BQ$25,Y$1,0) -> 0 | Z8: =IF(IF(AA9=0,0,AA8-AA9)<=0,0,IF(AA9=0,0,AA8-AA9)) -> 0 | AA8: =VLOOKUP($A16,$A$14:$BQ$25,AA$1,0) -> 0 | AB8: =IF(IF(AC9=0,0,AC8-AC9)<=0,0,IF(AC9=0,0,AC8-AC9)) -> 0 | AC8: =VLOOKUP($A16,$A$14:$BQ$25,AC$1,0) -> 0 | AD8: =IF(IF(AE9=0,0,AE8-AE9)<=0,0,IF(AE9=0,0,AE8-AE9)) -> 0 | AE8: =VLOOKUP($A16,$A$14:$BQ$25,AE$1,0) -> 0 | AF8: =IF(IF(AG9=0,0,AG8-AG9)<=0,0,IF(AG9=0,0,AG8-AG9)) -> 0 | AG8: =VLOOKUP($A16,$A$14:$BQ$25,AG$1,0) -> 0 | AH8: =IF(IF(AI9=0,0,AI8-AI9)<=0,0,IF(AI9=0,0,AI8-AI9)) -> 0 | AI8: =VLOOKUP($A16,$A$14:$BQ$25,AI$1,0) -> 45372 | AJ8: =IF(IF(AK9=0,0,AK8-AK9)<=0,0,IF(AK9=0,0,AK8-AK9)) -> 0 | AK8: =VLOOKUP($A16,$A$14:$BQ$25,AK$1,0) -> 0 | AL8: =IF(IF(AM9=0,0,AM8-AM9)<=0,0,IF(AM9=0,0,AM8-AM9)) -> 0 | AM8: =VLOOKUP($A16,$A$14:$BQ$25,AM$1,0) -> 0 | AN8: =IF(IF(AO9=0,0,AO8-AO9)<=0,0,IF(AO9=0,0,AO8-AO9)) -> 0 | AO8: =VLOOKUP($A16,$A$14:$BQ$25,AO$1,0) -> 0 | AP8: =IF(IF(AQ9=0,0,AQ8-AQ9)<=0,0,IF(AQ9=0,0,AQ8-AQ9)) -> 0 | AQ8: =VLOOKUP($A16,$A$14:$BQ$25,AQ$1,0) -> 0 | AR8: =IF(AS9=0,0,AS8-AS9) -> 0 | AS8: =VLOOKUP($A16,$A$14:$BQ$25,AS$1,0) -> 0 | AT8: =IF(IF(AU9=0,0,AU8-AU9)<=0,0,IF(AU9=0,0,AU8-AU9)) -> 0 | AU8: =VLOOKUP($A16,$A$14:$BQ$25,AU$1,0) -> 0 | AV8: =IF(IF(AW9=0,0,AW8-AW9)<=0,0,IF(AW9=0,0,AW8-AW9)) -> 0 | AW8: =VLOOKUP($A16,$A$14:$BQ$25,AW$1,0) -> 0 | AX8: =IF(IF(AY9=0,0,AY8-AY9)<=0,0,IF(AY9=0,0,AY8-AY9)) -> 0 | AY8: =VLOOKUP($A16,$A$14:$BQ$25,AY$1,0) -> 0 | AZ8: =IF(IF(BA9=0,0,BA8-BA9)<=0,0,IF(BA9=0,0,BA8-BA9)) -> 14 | BA8: =VLOOKUP($A16,$A$14:$BQ$25,BA$1,0) -> 45330 | BB8: =IF(IF(BC9=0,0,BC8-BC9)<=0,0,IF(BC9=0,0,BC8-BC9)) -> 0 | BC8: =VLOOKUP($A16,$A$14:$BQ$25,BC$1,0) -> 0 | BD8: =IF(IF(BE9=0,0,BE8-BE9)<=0,0,IF(BE9=0,0,BE8-BE9)) -> 0 | BE8: =VLOOKUP($A16,$A$14:$BQ$25,BE$1,0) -> 0 | BF8: =IF(IF(BG9=0,0,BG8-BG9)<=0,0,IF(BG9=0,0,BG8-BG9)) -> 0 | BG8: =VLOOKUP($A16,$A$14:$BQ$25,BG$1,0) -> 0 | BH8: =IF(IF(BI9=0,0,BI8-BI9)<=0,0,IF(BI9=0,0,BI8-BI9)) -> 0 | BI8: =VLOOKUP($A16,$A$14:$BQ$25,BI$1,0) -> 0 | BJ8: =IF(IF(BK9=0,0,BK8-BK9)<=0,0,IF(BK9=0,0,BK8-BK9)) -> 0 | BK8: =VLOOKUP($A16,$A$14:$BQ$25,BK$1,0) -> 45426 | BL8: =IF(IF(BM9=0,0,BM8-BM9)<=0,0,IF(BM9=0,0,BM8-BM9)) -> 0 | BM8: =VLOOKUP($A16,$A$14:$BQ$25,BM$1,0) -> 0 | BN8: =IF(IF(BO9=0,0,BO8-BO9)<=0,0,IF(BO9=0,0,BO8-BO9)) -> 87 | BO8: =VLOOKUP($A16,$A$14:$BQ$25,BO$1,0) -> 45723 | BP8: =IF(IF(BQ9=0,0,BQ8-BQ9)<=0,0,IF(BQ9=0,0,BQ8-BQ9)) -> 0 | BQ8: =VLOOKUP($A16,$A$14:$BQ$25,BQ$1,0) -> 0
B9: =IF(IF(C10=0,0,C9-C10)<=0,0,IF(C10=0,0,C9-C10)) -> 0 | C9: =VLOOKUP($A17,$A$14:$BQ$25,C$1,0) -> 0 | D9: =IF(IF(E10=0,0,E9-E10)<=0,0,IF(E10=0,0,E9-E10)) -> 0 | E9: =VLOOKUP($A17,$A$14:$BQ$25,E$1,0) -> 0 | F9: =IF(IF(G10=0,0,G9-G10)<=0,0,IF(G10=0,0,G9-G10)) -> 0 | G9: =VLOOKUP($A17,$A$14:$BQ$25,G$1,0) -> 0 | H9: =IF(IF(I10=0,0,I9-I10)<=0,0,IF(I10=0,0,I9-I10)) -> 0 | I9: =VLOOKUP($A17,$A$14:$BQ$25,I$1,0) -> 0 | J9: =IF(IF(K10=0,0,K9-K10)<=0,0,IF(K10=0,0,K9-K10)) -> 0 | K9: =VLOOKUP($A17,$A$14:$BQ$25,K$1,0) -> 0 | L9: =IF(IF(M10=0,0,M9-M10)<=0,0,IF(M10=0,0,M9-M10)) -> 0 | M9: =VLOOKUP($A17,$A$14:$BQ$25,M$1,0) -> 0 | N9: =IF(IF(O10=0,0,O9-O10)<=0,0,IF(O10=0,0,O9-O10)) -> 0 | O9: =VLOOKUP($A17,$A$14:$BQ$25,O$1,0) -> 0 | P9: =IF(IF(Q10=0,0,Q9-Q10)<=0,0,IF(Q10=0,0,Q9-Q10)) -> 0 | Q9: =VLOOKUP($A17,$A$14:$BQ$25,Q$1,0) -> 0 | R9: =IF(IF(S10=0,0,S9-S10)<=0,0,IF(S10=0,0,S9-S10)) -> 0 | S9: =VLOOKUP($A17,$A$14:$BQ$25,S$1,0) -> 0 | T9: =IF(IF(U10=0,0,U9-U10)<=0,0,IF(U10=0,0,U9-U10)) -> 0 | U9: =VLOOKUP($A17,$A$14:$BQ$25,U$1,0) -> 0 | V9: =IF(IF(W10=0,0,W9-W10)<=0,0,IF(W10=0,0,W9-W10)) -> 0 | W9: =VLOOKUP($A17,$A$14:$BQ$25,W$1,0) -> 0 | X9: =IF(IF(Y10=0,0,Y9-Y10)<=0,0,IF(Y10=0,0,Y9-Y10)) -> 0 | Y9: =VLOOKUP($A17,$A$14:$BQ$25,Y$1,0) -> 0 | Z9: =IF(IF(AA10=0,0,AA9-AA10)<=0,0,IF(AA10=0,0,AA9-AA10)) -> 0 | AA9: =VLOOKUP($A17,$A$14:$BQ$25,AA$1,0) -> 0 | AB9: =IF(IF(AC10=0,0,AC9-AC10)<=0,0,IF(AC10=0,0,AC9-AC10)) -> 0 | AC9: =VLOOKUP($A17,$A$14:$BQ$25,AC$1,0) -> 0 | AD9: =IF(IF(AE10=0,0,AE9-AE10)<=0,0,IF(AE10=0,0,AE9-AE10)) -> 0 | AE9: =VLOOKUP($A17,$A$14:$BQ$25,AE$1,0) -> 0 | AF9: =IF(IF(AG10=0,0,AG9-AG10)<=0,0,IF(AG10=0,0,AG9-AG10)) -> 0 | AG9: =VLOOKUP($A17,$A$14:$BQ$25,AG$1,0) -> 0 | AH9: =IF(IF(AI10=0,0,AI9-AI10)<=0,0,IF(AI10=0,0,AI9-AI10)) -> 0 | AI9: =VLOOKUP($A17,$A$14:$BQ$25,AI$1,0) -> 0 | AJ9: =IF(IF(AK10=0,0,AK9-AK10)<=0,0,IF(AK10=0,0,AK9-AK10)) -> 0 | AK9: =VLOOKUP($A17,$A$14:$BQ$25,AK$1,0) -> 0 | AL9: =IF(IF(AM10=0,0,AM9-AM10)<=0,0,IF(AM10=0,0,AM9-AM10)) -> 0 | AM9: =VLOOKUP($A17,$A$14:$BQ$25,AM$1,0) -> 0 | AN9: =IF(IF(AO10=0,0,AO9-AO10)<=0,0,IF(AO10=0,0,AO9-AO10)) -> 0 | AO9: =VLOOKUP($A17,$A$14:$BQ$25,AO$1,0) -> 0 | AP9: =IF(IF(AQ10=0,0,AQ9-AQ10)<=0,0,IF(AQ10=0,0,AQ9-AQ10)) -> 0 | AQ9: =VLOOKUP($A17,$A$14:$BQ$25,AQ$1,0) -> 0 | AR9: =IF(AS10=0,0,AS9-AS10) -> 0 | AS9: =VLOOKUP($A17,$A$14:$BQ$25,AS$1,0) -> 0 | AT9: =IF(IF(AU10=0,0,AU9-AU10)<=0,0,IF(AU10=0,0,AU9-AU10)) -> 0 | AU9: =VLOOKUP($A17,$A$14:$BQ$25,AU$1,0) -> 0 | AV9: =IF(IF(AW10=0,0,AW9-AW10)<=0,0,IF(AW10=0,0,AW9-AW10)) -> 0 | AW9: =VLOOKUP($A17,$A$14:$BQ$25,AW$1,0) -> 0 | AX9: =IF(IF(AY10=0,0,AY9-AY10)<=0,0,IF(AY10=0,0,AY9-AY10)) -> 0 | AY9: =VLOOKUP($A17,$A$14:$BQ$25,AY$1,0) -> 0 | AZ9: =IF(IF(BA10=0,0,BA9-BA10)<=0,0,IF(BA10=0,0,BA9-BA10)) -> 16 | BA9: =VLOOKUP($A17,$A$14:$BQ$25,BA$1,0) -> 45316 | BB9: =IF(IF(BC10=0,0,BC9-BC10)<=0,0,IF(BC10=0,0,BC9-BC10)) -> 0 | BC9: =VLOOKUP($A17,$A$14:$BQ$25,BC$1,0) -> 0 | BD9: =IF(IF(BE10=0,0,BE9-BE10)<=0,0,IF(BE10=0,0,BE9-BE10)) -> 0 | BE9: =VLOOKUP($A17,$A$14:$BQ$25,BE$1,0) -> 0 | BF9: =IF(IF(BG10=0,0,BG9-BG10)<=0,0,IF(BG10=0,0,BG9-BG10)) -> 0 | BG9: =VLOOKUP($A17,$A$14:$BQ$25,BG$1,0) -> 0 | BH9: =IF(IF(BI10=0,0,BI9-BI10)<=0,0,IF(BI10=0,0,BI9-BI10)) -> 0 | BI9: =VLOOKUP($A17,$A$14:$BQ$25,BI$1,0) -> 0 | BJ9: =IF(IF(BK10=0,0,BK9-BK10)<=0,0,IF(BK10=0,0,BK9-BK10)) -> 0 | BK9: =VLOOKUP($A17,$A$14:$BQ$25,BK$1,0) -> 0 | BL9: =IF(IF(BM10=0,0,BM9-BM10)<=0,0,IF(BM10=0,0,BM9-BM10)) -> 0 | BM9: =VLOOKUP($A17,$A$14:$BQ$25,BM$1,0) -> 0 | BN9: =IF(IF(BO10=0,0,BO9-BO10)<=0,0,IF(BO10=0,0,BO9-BO10)) -> 94 | BO9: =VLOOKUP($A17,$A$14:$BQ$25,BO$1,0) -> 45636 | BP9: =IF(IF(BQ10=0,0,BQ9-BQ10)<=0,0,IF(BQ10=0,0,BQ9-BQ10)) -> 0 | BQ9: =VLOOKUP($A17,$A$14:$BQ$25,BQ$1,0) -> 0
B10: =IF(IF(C11=0,0,C10-C11)<=0,0,IF(C11=0,0,C10-C11)) -> 0 | C10: =VLOOKUP($A18,$A$14:$BQ$25,C$1,0) -> 0 | D10: =IF(IF(E11=0,0,E10-E11)<=0,0,IF(E11=0,0,E10-E11)) -> 0 | E10: =VLOOKUP($A18,$A$14:$BQ$25,E$1,0) -> 0 | F10: =IF(IF(G11=0,0,G10-G11)<=0,0,IF(G11=0,0,G10-G11)) -> 0 | G10: =VLOOKUP($A18,$A$14:$BQ$25,G$1,0) -> 0 | H10: =IF(IF(I11=0,0,I10-I11)<=0,0,IF(I11=0,0,I10-I11)) -> 0 | I10: =VLOOKUP($A18,$A$14:$BQ$25,I$1,0) -> 0 | J10: =IF(IF(K11=0,0,K10-K11)<=0,0,IF(K11=0,0,K10-K11)) -> 0 | K10: =VLOOKUP($A18,$A$14:$BQ$25,K$1,0) -> 0 | L10: =IF(IF(M11=0,0,M10-M11)<=0,0,IF(M11=0,0,M10-M11)) -> 0 | M10: =VLOOKUP($A18,$A$14:$BQ$25,M$1,0) -> 0 | N10: =IF(IF(O11=0,0,O10-O11)<=0,0,IF(O11=0,0,O10-O11)) -> 0 | O10: =VLOOKUP($A18,$A$14:$BQ$25,O$1,0) -> 0 | P10: =IF(IF(Q11=0,0,Q10-Q11)<=0,0,IF(Q11=0,0,Q10-Q11)) -> 0 | Q10: =VLOOKUP($A18,$A$14:$BQ$25,Q$1,0) -> 0 | R10: =IF(IF(S11=0,0,S10-S11)<=0,0,IF(S11=0,0,S10-S11)) -> 0 | S10: =VLOOKUP($A18,$A$14:$BQ$25,S$1,0) -> 0 | T10: =IF(IF(U11=0,0,U10-U11)<=0,0,IF(U11=0,0,U10-U11)) -> 0 | U10: =VLOOKUP($A18,$A$14:$BQ$25,U$1,0) -> 0 | V10: =IF(IF(W11=0,0,W10-W11)<=0,0,IF(W11=0,0,W10-W11)) -> 0 | W10: =VLOOKUP($A18,$A$14:$BQ$25,W$1,0) -> 0 | X10: =IF(IF(Y11=0,0,Y10-Y11)<=0,0,IF(Y11=0,0,Y10-Y11)) -> 0 | Y10: =VLOOKUP($A18,$A$14:$BQ$25,Y$1,0) -> 0 | Z10: =IF(IF(AA11=0,0,AA10-AA11)<=0,0,IF(AA11=0,0,AA10-AA11)) -> 0 | AA10: =VLOOKUP($A18,$A$14:$BQ$25,AA$1,0) -> 0 | AB10: =IF(IF(AC11=0,0,AC10-AC11)<=0,0,IF(AC11=0,0,AC10-AC11)) -> 0 | AC10: =VLOOKUP($A18,$A$14:$BQ$25,AC$1,0) -> 0 | AD10: =IF(IF(AE11=0,0,AE10-AE11)<=0,0,IF(AE11=0,0,AE10-AE11)) -> 0 | AE10: =VLOOKUP($A18,$A$14:$BQ$25,AE$1,0) -> 0 | AF10: =IF(IF(AG11=0,0,AG10-AG11)<=0,0,IF(AG11=0,0,AG10-AG11)) -> 0 | AG10: =VLOOKUP($A18,$A$14:$BQ$25,AG$1,0) -> 0 | AH10: =IF(IF(AI11=0,0,AI10-AI11)<=0,0,IF(AI11=0,0,AI10-AI11)) -> 0 | AI10: =VLOOKUP($A18,$A$14:$BQ$25,AI$1,0) -> 0 | AJ10: =IF(IF(AK11=0,0,AK10-AK11)<=0,0,IF(AK11=0,0,AK10-AK11)) -> 0 | AK10: =VLOOKUP($A18,$A$14:$BQ$25,AK$1,0) -> 0 | AL10: =IF(IF(AM11=0,0,AM10-AM11)<=0,0,IF(AM11=0,0,AM10-AM11)) -> 0 | AM10: =VLOOKUP($A18,$A$14:$BQ$25,AM$1,0) -> 0 | AN10: =IF(IF(AO11=0,0,AO10-AO11)<=0,0,IF(AO11=0,0,AO10-AO11)) -> 0 | AO10: =VLOOKUP($A18,$A$14:$BQ$25,AO$1,0) -> 0 | AP10: =IF(IF(AQ11=0,0,AQ10-AQ11)<=0,0,IF(AQ11=0,0,AQ10-AQ11)) -> 0 | AQ10: =VLOOKUP($A18,$A$14:$BQ$25,AQ$1,0) -> 0 | AR10: =IF(AS11=0,0,AS10-AS11) -> 0 | AS10: =VLOOKUP($A18,$A$14:$BQ$25,AS$1,0) -> 0 | AT10: =IF(IF(AU11=0,0,AU10-AU11)<=0,0,IF(AU11=0,0,AU10-AU11)) -> 0 | AU10: =VLOOKUP($A18,$A$14:$BQ$25,AU$1,0) -> 0 | AV10: =IF(IF(AW11=0,0,AW10-AW11)<=0,0,IF(AW11=0,0,AW10-AW11)) -> 0 | AW10: =VLOOKUP($A18,$A$14:$BQ$25,AW$1,0) -> 0 | AX10: =IF(IF(AY11=0,0,AY10-AY11)<=0,0,IF(AY11=0,0,AY10-AY11)) -> 0 | AY10: =VLOOKUP($A18,$A$14:$BQ$25,AY$1,0) -> 0 | AZ10: =IF(IF(BA11=0,0,BA10-BA11)<=0,0,IF(BA11=0,0,BA10-BA11)) -> 0 | BA10: =VLOOKUP($A18,$A$14:$BQ$25,BA$1,0) -> 45300 | BB10: =IF(IF(BC11=0,0,BC10-BC11)<=0,0,IF(BC11=0,0,BC10-BC11)) -> 0 | BC10: =VLOOKUP($A18,$A$14:$BQ$25,BC$1,0) -> 0 | BD10: =IF(IF(BE11=0,0,BE10-BE11)<=0,0,IF(BE11=0,0,BE10-BE11)) -> 0 | BE10: =VLOOKUP($A18,$A$14:$BQ$25,BE$1,0) -> 0 | BF10: =IF(IF(BG11=0,0,BG10-BG11)<=0,0,IF(BG11=0,0,BG10-BG11)) -> 0 | BG10: =VLOOKUP($A18,$A$14:$BQ$25,BG$1,0) -> 0 | BH10: =IF(IF(BI11=0,0,BI10-BI11)<=0,0,IF(BI11=0,0,BI10-BI11)) -> 0 | BI10: =VLOOKUP($A18,$A$14:$BQ$25,BI$1,0) -> 0 | BJ10: =IF(IF(BK11=0,0,BK10-BK11)<=0,0,IF(BK11=0,0,BK10-BK11)) -> 0 | BK10: =VLOOKUP($A18,$A$14:$BQ$25,BK$1,0) -> 0 | BL10: =IF(IF(BM11=0,0,BM10-BM11)<=0,0,IF(BM11=0,0,BM10-BM11)) -> 0 | BM10: =VLOOKUP($A18,$A$14:$BQ$25,BM$1,0) -> 0 | BN10: =IF(IF(BO11=0,0,BO10-BO11)<=0,0,IF(BO11=0,0,BO10-BO11)) -> 29 | BO10: =VLOOKUP($A18,$A$14:$BQ$25,BO$1,0) -> 45542 | BP10: =IF(IF(BQ11=0,0,BQ10-BQ11)<=0,0,IF(BQ11=0,0,BQ10-BQ11)) -> 0 | BQ10: =VLOOKUP($A18,$A$14:$BQ$25,BQ$1,0) -> 0
B11: =IF(IF(C12=0,0,C11-C12)<=0,0,IF(C12=0,0,C11-C12)) -> 0 | C11: =VLOOKUP($A19,$A$14:$BQ$25,C$1,0) -> 0 | D11: =IF(IF(E12=0,0,E11-E12)<=0,0,IF(E12=0,0,E11-E12)) -> 0 | E11: =VLOOKUP($A19,$A$14:$BQ$25,E$1,0) -> 0 | F11: =IF(IF(G12=0,0,G11-G12)<=0,0,IF(G12=0,0,G11-G12)) -> 0 | G11: =VLOOKUP($A19,$A$14:$BQ$25,G$1,0) -> 0 | H11: =IF(IF(I12=0,0,I11-I12)<=0,0,IF(I12=0,0,I11-I12)) -> 0 | I11: =VLOOKUP($A19,$A$14:$BQ$25,I$1,0) -> 0 | J11: =IF(IF(K12=0,0,K11-K12)<=0,0,IF(K12=0,0,K11-K12)) -> 0 | K11: =VLOOKUP($A19,$A$14:$BQ$25,K$1,0) -> 0 | L11: =IF(IF(M12=0,0,M11-M12)<=0,0,IF(M12=0,0,M11-M12)) -> 0 | M11: =VLOOKUP($A19,$A$14:$BQ$25,M$1,0) -> 0 | N11: =IF(IF(O12=0,0,O11-O12)<=0,0,IF(O12=0,0,O11-O12)) -> 0 | O11: =VLOOKUP($A19,$A$14:$BQ$25,O$1,0) -> 0 | P11: =IF(IF(Q12=0,0,Q11-Q12)<=0,0,IF(Q12=0,0,Q11-Q12)) -> 0 | Q11: =VLOOKUP($A19,$A$14:$BQ$25,Q$1,0) -> 0 | R11: =IF(IF(S12=0,0,S11-S12)<=0,0,IF(S12=0,0,S11-S12)) -> 0 | S11: =VLOOKUP($A19,$A$14:$BQ$25,S$1,0) -> 0 | T11: =IF(IF(U12=0,0,U11-U12)<=0,0,IF(U12=0,0,U11-U12)) -> 0 | U11: =VLOOKUP($A19,$A$14:$BQ$25,U$1,0) -> 0 | V11: =IF(IF(W12=0,0,W11-W12)<=0,0,IF(W12=0,0,W11-W12)) -> 0 | W11: =VLOOKUP($A19,$A$14:$BQ$25,W$1,0) -> 0 | X11: =IF(IF(Y12=0,0,Y11-Y12)<=0,0,IF(Y12=0,0,Y11-Y12)) -> 0 | Y11: =VLOOKUP($A19,$A$14:$BQ$25,Y$1,0) -> 0 | Z11: =IF(IF(AA12=0,0,AA11-AA12)<=0,0,IF(AA12=0,0,AA11-AA12)) -> 0 | AA11: =VLOOKUP($A19,$A$14:$BQ$25,AA$1,0) -> 0 | AB11: =IF(IF(AC12=0,0,AC11-AC12)<=0,0,IF(AC12=0,0,AC11-AC12)) -> 0 | AC11: =VLOOKUP($A19,$A$14:$BQ$25,AC$1,0) -> 0 | AD11: =IF(IF(AE12=0,0,AE11-AE12)<=0,0,IF(AE12=0,0,AE11-AE12)) -> 0 | AE11: =VLOOKUP($A19,$A$14:$BQ$25,AE$1,0) -> 0 | AF11: =IF(IF(AG12=0,0,AG11-AG12)<=0,0,IF(AG12=0,0,AG11-AG12)) -> 0 | AG11: =VLOOKUP($A19,$A$14:$BQ$25,AG$1,0) -> 0 | AH11: =IF(IF(AI12=0,0,AI11-AI12)<=0,0,IF(AI12=0,0,AI11-AI12)) -> 0 | AI11: =VLOOKUP($A19,$A$14:$BQ$25,AI$1,0) -> 0 | AJ11: =IF(IF(AK12=0,0,AK11-AK12)<=0,0,IF(AK12=0,0,AK11-AK12)) -> 0 | AK11: =VLOOKUP($A19,$A$14:$BQ$25,AK$1,0) -> 0 | AL11: =IF(IF(AM12=0,0,AM11-AM12)<=0,0,IF(AM12=0,0,AM11-AM12)) -> 0 | AM11: =VLOOKUP($A19,$A$14:$BQ$25,AM$1,0) -> 0 | AN11: =IF(IF(AO12=0,0,AO11-AO12)<=0,0,IF(AO12=0,0,AO11-AO12)) -> 0 | AO11: =VLOOKUP($A19,$A$14:$BQ$25,AO$1,0) -> 0 | AP11: =IF(IF(AQ12=0,0,AQ11-AQ12)<=0,0,IF(AQ12=0,0,AQ11-AQ12)) -> 0 | AQ11: =VLOOKUP($A19,$A$14:$BQ$25,AQ$1,0) -> 0 | AR11: =IF(AS12=0,0,AS11-AS12) -> 0 | AS11: =VLOOKUP($A19,$A$14:$BQ$25,AS$1,0) -> 0 | AT11: =IF(IF(AU12=0,0,AU11-AU12)<=0,0,IF(AU12=0,0,AU11-AU12)) -> 0 | AU11: =VLOOKUP($A19,$A$14:$BQ$25,AU$1,0) -> 0 | AV11: =IF(IF(AW12=0,0,AW11-AW12)<=0,0,IF(AW12=0,0,AW11-AW12)) -> 0 | AW11: =VLOOKUP($A19,$A$14:$BQ$25,AW$1,0) -> 0 | AX11: =IF(IF(AY12=0,0,AY11-AY12)<=0,0,IF(AY12=0,0,AY11-AY12)) -> 0 | AY11: =VLOOKUP($A19,$A$14:$BQ$25,AY$1,0) -> 0 | AZ11: =IF(IF(BA12=0,0,BA11-BA12)<=0,0,IF(BA12=0,0,BA11-BA12)) -> 0 | BA11: =VLOOKUP($A19,$A$14:$BQ$25,BA$1,0) -> 0 | BB11: =IF(IF(BC12=0,0,BC11-BC12)<=0,0,IF(BC12=0,0,BC11-BC12)) -> 0 | BC11: =VLOOKUP($A19,$A$14:$BQ$25,BC$1,0) -> 0 | BD11: =IF(IF(BE12=0,0,BE11-BE12)<=0,0,IF(BE12=0,0,BE11-BE12)) -> 0 | BE11: =VLOOKUP($A19,$A$14:$BQ$25,BE$1,0) -> 0 | BF11: =IF(IF(BG12=0,0,BG11-BG12)<=0,0,IF(BG12=0,0,BG11-BG12)) -> 0 | BG11: =VLOOKUP($A19,$A$14:$BQ$25,BG$1,0) -> 0 | BH11: =IF(IF(BI12=0,0,BI11-BI12)<=0,0,IF(BI12=0,0,BI11-BI12)) -> 0 | BI11: =VLOOKUP($A19,$A$14:$BQ$25,BI$1,0) -> 0 | BJ11: =IF(IF(BK12=0,0,BK11-BK12)<=0,0,IF(BK12=0,0,BK11-BK12)) -> 0 | BK11: =VLOOKUP($A19,$A$14:$BQ$25,BK$1,0) -> 0 | BL11: =IF(IF(BM12=0,0,BM11-BM12)<=0,0,IF(BM12=0,0,BM11-BM12)) -> 0 | BM11: =VLOOKUP($A19,$A$14:$BQ$25,BM$1,0) -> 0 | BN11: =IF(IF(BO12=0,0,BO11-BO12)<=0,0,IF(BO12=0,0,BO11-BO12)) -> 17 | BO11: =VLOOKUP($A19,$A$14:$BQ$25,BO$1,0) -> 45513 | BP11: =IF(IF(BQ12=0,0,BQ11-BQ12)<=0,0,IF(BQ12=0,0,BQ11-BQ12)) -> 0 | BQ11: =VLOOKUP($A19,$A$14:$BQ$25,BQ$1,0) -> 0
C12: =VLOOKUP($A20,$A$14:$BQ$25,C$1,0) -> 0 | E12: =VLOOKUP($A20,$A$14:$BQ$25,E$1,0) -> 0 | G12: =VLOOKUP($A20,$A$14:$BQ$25,G$1,0) -> 0 | I12: =VLOOKUP($A20,$A$14:$BQ$25,I$1,0) -> 0 | K12: =VLOOKUP($A20,$A$14:$BQ$25,K$1,0) -> 0 | M12: =VLOOKUP($A20,$A$14:$BQ$25,M$1,0) -> 0 | O12: =VLOOKUP($A20,$A$14:$BQ$25,O$1,0) -> 0 | Q12: =VLOOKUP($A20,$A$14:$BQ$25,Q$1,0) -> 0 | S12: =VLOOKUP($A20,$A$14:$BQ$25,S$1,0) -> 0 | U12: =VLOOKUP($A20,$A$14:$BQ$25,U$1,0) -> 0 | W12: =VLOOKUP($A20,$A$14:$BQ$25,W$1,0) -> 0 | Y12: =VLOOKUP($A20,$A$14:$BQ$25,Y$1,0) -> 0 | AA12: =VLOOKUP($A20,$A$14:$BQ$25,AA$1,0) -> 0 | AC12: =VLOOKUP($A20,$A$14:$BQ$25,AC$1,0) -> 0 | AE12: =VLOOKUP($A20,$A$14:$BQ$25,AE$1,0) -> 0 | AG12: =VLOOKUP($A20,$A$14:$BQ$25,AG$1,0) -> 0 | AI12: =VLOOKUP($A20,$A$14:$BQ$25,AI$1,0) -> 0 | AK12: =VLOOKUP($A20,$A$14:$BQ$25,AK$1,0) -> 0 | AM12: =VLOOKUP($A20,$A$14:$BQ$25,AM$1,0) -> 0 | AO12: =VLOOKUP($A20,$A$14:$BQ$25,AO$1,0) -> 0 | AQ12: =VLOOKUP($A20,$A$14:$BQ$25,AQ$1,0) -> 0 | AS12: =VLOOKUP($A20,$A$14:$BQ$25,AS$1,0) -> 0 | AU12: =VLOOKUP($A20,$A$14:$BQ$25,AU$1,0) -> 0 | AW12: =VLOOKUP($A20,$A$14:$BQ$25,AW$1,0) -> 0 | AY12: =VLOOKUP($A20,$A$14:$BQ$25,AY$1,0) -> 0 | BA12: =VLOOKUP($A20,$A$14:$BQ$25,BA$1,0) -> 0 | BC12: =VLOOKUP($A20,$A$14:$BQ$25,BC$1,0) -> 0 | BE12: =VLOOKUP($A20,$A$14:$BQ$25,BE$1,0) -> 0 | BG12: =VLOOKUP($A20,$A$14:$BQ$25,BG$1,0) -> 0 | BI12: =VLOOKUP($A20,$A$14:$BQ$25,BI$1,0) -> 0 | BK12: =VLOOKUP($A20,$A$14:$BQ$25,BK$1,0) -> 0 | BM12: =VLOOKUP($A20,$A$14:$BQ$25,BM$1,0) -> 0 | BO12: =VLOOKUP($A20,$A$14:$BQ$25,BO$1,0) -> 45496 | BQ12: =VLOOKUP($A20,$A$14:$BQ$25,BQ$1,0) -> 0
A14: =ROW()-13 -> 1 | O14: 45876 | AI14: 45784 | BA14: 45663 | BK14: 45904 | BO14: 45958 | BQ14: 45330
A15: =ROW()-13 -> 2 | AI15: 45512 | BA15: 45372 | BK15: 45513 | BO15: 45912 | BQ15: 45300
A16: =ROW()-13 -> 3 | AI16: 45372 | BA16: 45330 | BK16: 45426 | BO16: 45723
A17: =ROW()-13 -> 4 | BA17: 45316 | BO17: 45636
A18: =ROW()-13 -> 5 | BA18: 45300 | BO18: 45542
A19: =ROW()-13 -> 6 | BO19: 45513
A20: =ROW()-13 -> 7 | BO20: 45496
A21: =ROW()-13 -> 8 | BO21: 45482
A22: =ROW()-13 -> 9 | BO22: 45468
A23: =ROW()-13 -> 10
A24: =ROW()-13 -> 11
A25: =ROW()-13 -> 12
A26: =ROW()-13 -> 13
A27: =ROW()-13 -> 14
A28: =ROW()-13 -> 15
A29: =ROW()-13 -> 16
A30: =ROW()-13 -> 17
A31: =ROW()-13 -> 18
A32: =ROW()-13 -> 19
A33: =ROW()-13 -> 20
A34: =ROW()-13 -> 21
... A113: =ROW()-13 -> 100

Sheet 참고.컴프 오일 주기
A1: 1 | B1: 2 | C1: 3 | D1: 4 | E1: 5 | F1: 6 | G1: 7 | H1: 8 | I1: 9 | J1: 10 | K1: 11 | L1: 12 | M1: 13 | N1: 14 | O1: 15 | P1: 16 | Q1: 17 | R1: 18 | S1: 19 | T1: 20 | U1: 21 | V1: 22 | W1: 23 | X1: 24 | Y1: 25 | Z1: 26 | AA1: 27 | AB1: 28 | AC1: 29 | AD1: 30 | AE1: 31 | AF1: 32 | AG1: 33 | AH1: 34 | AI1: 35 | AJ1: 36 | AK1: 37 | AL1: 38 | AM1: 39 | AN1: 40 | AO1: 41 | AP1: 42 | AQ1: 43 | AR1: 44 | AS1: 45 | AT1: 46 | AU1: 47 | AV1: 48 | AW1: 49 | AX1: 50 | AY1: 51 | AZ1: 52 | BA1: 53 | BB1: 54 | BC1: 55 | BD1: 56 | BE1: 57 | BF1: 58 | BG1: 59 | BH1: 60 | BI1: 61 | BJ1: 62 | BK1: 63 | BL1: 64 | BM1: 65 | BN1: 66 | BO1: 67 | BP1: 68 | BQ1: 69
A2: 배수 | B2: 8층 | J2: 7층 | P2: 6층 | V2: 5층 | AB2: 3층 | AH2: 2층 | AL2: 1층 | AR2: B1층 | AX2: B2층 | BD2: B3층 | BH2: B4층 | BN2: B5층
B3: 계단 위 | D3: 연구동 | H3: 사무동 | J3: 연구동 | N3: 사무동 | P3: 연구동 | T3: 사무동 | V3: 연구동 | Z3: 사무동 | AB3: 연구동 | AF3: 사무동 | AH3: 연구동 | AJ3: 사무동 | AL3: 연구동 | AP3: 사무동
B4: PS실 | D4: 공조실 | F4: PS실 | H4: PS실 | J4: 공조실 | L4: PS실 | N4: PS실 | P4: 공조실 | R4: PS실 | T4: PS실 | V4: 공조실 | X4: PS실 | Z4: PS실 | AB4: 공조실 | AD4: PS실 | AF4: PS실 | AH4: PS실 | AJ4: PS실 | AL4: 공조실 | AN4: PS실 | AP4: PS실 | AR4: 공조실 | AT4: 식당 | AV4: 화장실 | AX4: 공조실 | AZ4: CPX실 | BB4: PS실 | BD4: 휀룸1 | BF4: 기사대기실 | BH4: 휀룸1 | BJ4: 기계실 | BL4: 창고 | BN4: 휀룸1 | BP4: 휀룸2
A5: 트렌드
A6: 이번 주기 | B6: =IF(IF(C7=0,0,C6-C7)<=0,0,IF(C7=0,0,C6-C7)) -> 431 | C6: =VLOOKUP($A15,$A$15:$BQ$26,C$1,0) -> 45912 | D6: =IF(IF(E7=0,0,E6-E7)<=0,0,IF(E7=0,0,E6-E7)) -> 15 | E6: =VLOOKUP($A15,$A$15:$BQ$26,E$1,0) -> 46024 | F6: =IF(IF(G7=0,0,G6-G7)<=0,0,IF(G7=0,0,G6-G7)) -> 0 | G6: =VLOOKUP($A15,$A$15:$BQ$26,G$1,0) -> 0 | H6: =IF(IF(I7=0,0,I6-I7)<=0,0,IF(I7=0,0,I6-I7)) -> 0 | I6: =VLOOKUP($A15,$A$15:$BQ$26,I$1,0) -> 0 | J6: =IF(IF(K7=0,0,K6-K7)<=0,0,IF(K7=0,0,K6-K7)) -> 0 | K6: =VLOOKUP($A15,$A$15:$BQ$26,K$1,0) -> 45912 | L6: =IF(IF(M7=0,0,M6-M7)<=0,0,IF(M7=0,0,M6-M7)) -> 0 | M6: =VLOOKUP($A15,$A$15:$BQ$26,M$1,0) -> 0 | N6: =IF(IF(O7=0,0,O6-O7)<=0,0,IF(O7=0,0,O6-O7)) -> 234 | O6: =VLOOKUP($A15,$A$15:$BQ$26,O$1,0) -> 45912 | P6: =IF(IF(Q7=0,0,Q6-Q7)<=0,0,IF(Q7=0,0,Q6-Q7)) -> 257 | Q6: =VLOOKUP($A15,$A$15:$BQ$26,Q$1,0) -> 45784 | R6: =IF(IF(S7=0,0,S6-S7)<=0,0,IF(S7=0,0,S6-S7)) -> 61 | S6: =VLOOKUP($A15,$A$15:$BQ$26,S$1,0) -> 45845 | T6: =IF(IF(U7=0,0,U6-U7)<=0,0,IF(U7=0,0,U6-U7)) -> 29 | U6: =VLOOKUP($A15,$A$15:$BQ$26,U$1,0) -> 46072 | V6: =IF(IF(W7=0,0,W6-W7)<=0,0,IF(W7=0,0,W6-W7)) -> 304 | W6: =VLOOKUP($A15,$A$15:$BQ$26,W$1,0) -> 45831 | X6: =IF(IF(Y7=0,0,Y6-Y7)<=0,0,IF(Y7=0,0,Y6-Y7)) -> 0 | Y6: =VLOOKUP($A15,$A$15:$BQ$26,Y$1,0) -> 46003 | Z6: =IF(IF(AA7=0,0,AA6-AA7)<=0,0,IF(AA7=0,0,AA6-AA7)) -> 95 | AA6: =VLOOKUP($A15,$A$15:$BQ$26,AA$1,0) -> 45912 | AB6: =IF(IF(AC7=0,0,AC6-AC7)<=0,0,IF(AC7=0,0,AC6-AC7)) -> 0 | AC6: =VLOOKUP($A15,$A$15:$BQ$26,AC$1,0) -> 45967 | AD6: =IF(IF(AE7=0,0,AE6-AE7)<=0,0,IF(AE7=0,0,AE6-AE7)) -> 0 | AE6: =VLOOKUP($A15,$A$15:$BQ$26,AE$1,0) -> 0 | AF6: =IF(IF(AG7=0,0,AG6-AG7)<=0,0,IF(AG7=0,0,AG6-AG7)) -> 114 | AG6: =VLOOKUP($A15,$A$15:$BQ$26,AG$1,0) -> 46072 | AH6: =IF(IF(AI7=0,0,AI6-AI7)<=0,0,IF(AI7=0,0,AI6-AI7)) -> 335 | AI6: =VLOOKUP($A15,$A$15:$BQ$26,AI$1,0) -> 45862 | AJ6: =IF(IF(AK7=0,0,AK6-AK7)<=0,0,IF(AK7=0,0,AK6-AK7)) -> 437 | AK6: =VLOOKUP($A15,$A$15:$BQ$26,AK$1,0) -> 45862 | AL6: =IF(IF(AM7=0,0,AM6-AM7)<=0,0,IF(AM7=0,0,AM6-AM7)) -> 0 | AM6: =VLOOKUP($A15,$A$15:$BQ$26,AM$1,0) -> 45299 | AN6: =IF(IF(AO7=0,0,AO6-AO7)<=0,0,IF(AO7=0,0,AO6-AO7)) -> 0 | AO6: =VLOOKUP($A15,$A$15:$BQ$26,AO$1,0) -> 46003 | AP6: =IF(IF(AQ7=0,0,AQ6-AQ7)<=0,0,IF(AQ7=0,0,AQ6-AQ7)) -> 0 | AQ6: =VLOOKUP($A15,$A$15:$BQ$26,AQ$1,0) -> 45737 | AR6: =IF(IF(AS7=0,0,AS6-AS7)<=0,0,IF(AS7=0,0,AS6-AS7)) -> 196 | AS6: =VLOOKUP($A15,$A$15:$BQ$26,AS$1,0) -> 45663 | AT6: =IF(IF(AU7=0,0,AU6-AU7)<=0,0,IF(AU7=0,0,AU6-AU7)) -> 56 | AU6: =VLOOKUP($A15,$A$15:$BQ$26,AU$1,0) -> 45482 | AV6: =IF(IF(AW7=0,0,AW6-AW7)<=0,0,IF(AW7=0,0,AW6-AW7)) -> 0 | AW6: =VLOOKUP($A15,$A$15:$BQ$26,AW$1,0) -> 0 | AX6: =IF(IF(AY7=0,0,AY6-AY7)<=0,0,IF(AY7=0,0,AY6-AY7)) -> 126 | AY6: =VLOOKUP($A15,$A$15:$BQ$26,AY$1,0) -> 46003 | AZ6: =IF(IF(BA7=0,0,BA6-BA7)<=0,0,IF(BA7=0,0,BA6-BA7)) -> 0 | BA6: =VLOOKUP($A15,$A$15:$BQ$26,BA$1,0) -> 45344 | BB6: =IF(IF(BC7=0,0,BC6-BC7)<=0,0,IF(BC7=0,0,BC6-BC7)) -> 206 | BC6: =VLOOKUP($A15,$A$15:$BQ$26,BC$1,0) -> 46003 | BD6: =IF(IF(BE7=0,0,BE6-BE7)<=0,0,IF(BE7=0,0,BE6-BE7)) -> 63 | BE6: =VLOOKUP($A15,$A$15:$BQ$26,BE$1,0) -> 46003 | BF6: =IF(IF(BG7=0,0,BG6-BG7)<=0,0,IF(BG7=0,0,BG6-BG7)) -> 28 | BG6: =VLOOKUP($A15,$A$15:$BQ$26,BG$1,0) -> 46031 | BH6: =IF(IF(BI7=0,0,BI6-BI7)<=0,0,IF(BI7=0,0,BI6-BI7)) -> 0 | BI6: =VLOOKUP($A15,$A$15:$BQ$26,BI$1,0) -> 0 | BJ6: =IF(IF(BK7=0,0,BK6-BK7)<=0,0,IF(BK7=0,0,BK6-BK7)) -> 19 | BK6: =VLOOKUP($A15,$A$15:$BQ$26,BK$1,0) -> 46043 | BL6: =IF(IF(BM7=0,0,BM6-BM7)<=0,0,IF(BM7=0,0,BM6-BM7)) -> 286 | BM6: =VLOOKUP($A15,$A$15:$BQ$26,BM$1,0) -> 45586 | BN6: =IF(IF(BO7=0,0,BO6-BO7)<=0,0,IF(BO7=0,0,BO6-BO7)) -> 0 | BO6: =VLOOKUP($A15,$A$15:$BQ$26,BO$1,0) -> 45300 | BP6: =IF(IF(BQ7=0,0,BQ6-BQ7)<=0,0,IF(BQ7=0,0,BQ6-BQ7)) -> 476 | BQ6: =VLOOKUP($A15,$A$15:$BQ$26,BQ$1,0) -> 45958
A7: 지난 주기 | B7: =IF(IF(C8=0,0,C7-C8)<=0,0,IF(C8=0,0,C7-C8)) -> 0 | C7: =VLOOKUP($A16,$A$15:$BQ$26,C$1,0) -> 45481 | D7: =IF(IF(E8=0,0,E7-E8)<=0,0,IF(E8=0,0,E7-E8)) -> 13 | E7: =VLOOKUP($A16,$A$15:$BQ$26,E$1,0) -> 46009 | F7: =IF(IF(G8=0,0,G7-G8)<=0,0,IF(G8=0,0,G7-G8)) -> 0 | G7: =VLOOKUP($A16,$A$15:$BQ$26,G$1,0) -> 0 | H7: =IF(IF(I8=0,0,I7-I8)<=0,0,IF(I8=0,0,I7-I8)) -> 0 | I7: =VLOOKUP($A16,$A$15:$BQ$26,I$1,0) -> 0 | J7: =IF(IF(K8=0,0,K7-K8)<=0,0,IF(K8=0,0,K7-K8)) -> 0 | K7: =VLOOKUP($A16,$A$15:$BQ$26,K$1,0) -> 0 | L7: =IF(IF(M8=0,0,M7-M8)<=0,0,IF(M8=0,0,M7-M8)) -> 0 | M7: =VLOOKUP($A16,$A$15:$BQ$26,M$1,0) -> 0 | N7: =IF(IF(O8=0,0,O7-O8)<=0,0,IF(O8=0,0,O7-O8)) -> 441 | O7: =VLOOKUP($A16,$A$15:$BQ$26,O$1,0) -> 45678 | P7: =IF(IF(Q8=0,0,Q7-Q8)<=0,0,IF(Q8=0,0,Q7-Q8)) -> 183 | Q7: =VLOOKUP($A16,$A$15:$BQ$26,Q$1,0) -> 45527 | R7: =IF(IF(S8=0,0,S7-S8)<=0,0,IF(S8=0,0,S7-S8)) -> 264 | S7: =VLOOKUP($A16,$A$15:$BQ$26,S$1,0) -> 45784 | T7: =IF(IF(U8=0,0,U7-U8)<=0,0,IF(U8=0,0,U7-U8)) -> 13 | U7: =VLOOKUP($A16,$A$15:$BQ$26,U$1,0) -> 46043 | V7: =IF(IF(W8=0,0,W7-W8)<=0,0,IF(W8=0,0,W7-W8)) -> 0 | W7: =VLOOKUP($A16,$A$15:$BQ$26,W$1,0) -> 45527 | X7: =IF(IF(Y8=0,0,Y7-Y8)<=0,0,IF(Y8=0,0,Y7-Y8)) -> 0 | Y7: =VLOOKUP($A16,$A$15:$BQ$26,Y$1,0) -> 0 | Z7: =IF(IF(AA8=0,0,AA7-AA8)<=0,0,IF(AA8=0,0,AA7-AA8)) -> 81 | AA7: =VLOOKUP($A16,$A$15:$BQ$26,AA$1,0) -> 45817 | AB7: =IF(IF(AC8=0,0,AC7-AC8)<=0,0,IF(AC8=0,0,AC7-AC8)) -> 0 | AC7: =VLOOKUP($A16,$A$15:$BQ$26,AC$1,0) -> 0 | AD7: =IF(IF(AE8=0,0,AE7-AE8)<=0,0,IF(AE8=0,0,AE7-AE8)) -> 0 | AE7: =VLOOKUP($A16,$A$15:$BQ$26,AE$1,0) -> 0 | AF7: =IF(IF(AG8=0,0,AG7-AG8)<=0,0,IF(AG8=0,0,AG7-AG8)) -> 127 | AG7: =VLOOKUP($A16,$A$15:$BQ$26,AG$1,0) -> 45958 | AH7: =IF(IF(AI8=0,0,AI7-AI8)<=0,0,IF(AI8=0,0,AI7-AI8)) -> 309 | AI7: =VLOOKUP($A16,$A$15:$BQ$26,AI$1,0) -> 45527 | AJ7: =IF(IF(AK8=0,0,AK7-AK8)<=0,0,IF(AK8=0,0,AK7-AK8)) -> 0 | AK7: =VLOOKUP($A16,$A$15:$BQ$26,AK$1,0) -> 45425 | AL7: =IF(IF(AM8=0,0,AM7-AM8)<=0,0,IF(AM8=0,0,AM7-AM8)) -> 0 | AM7: =VLOOKUP($A16,$A$15:$BQ$26,AM$1,0) -> 0 | AN7: =IF(IF(AO8=0,0,AO7-AO8)<=0,0,IF(AO8=0,0,AO7-AO8)) -> 0 | AO7: =VLOOKUP($A16,$A$15:$BQ$26,AO$1,0) -> 0 | AP7: =IF(IF(AQ8=0,0,AQ7-AQ8)<=0,0,IF(AQ8=0,0,AQ7-AQ8)) -> 0 | AQ7: =VLOOKUP($A16,$A$15:$BQ$26,AQ$1,0) -> 0 | AR7: =IF(AS8=0,0,AS7-AS8) -> 312 | AS7: =VLOOKUP($A16,$A$15:$BQ$26,AS$1,0) -> 45467 | AT7: =IF(IF(AU8=0,0,AU7-AU8)<=0,0,IF(AU8=0,0,AU7-AU8)) -> 82 | AU7: =VLOOKUP($A16,$A$15:$BQ$26,AU$1,0) -> 45426 | AV7: =IF(IF(AW8=0,0,AW7-AW8)<=0,0,IF(AW8=0,0,AW7-AW8)) -> 0 | AW7: =VLOOKUP($A16,$A$15:$BQ$26,AW$1,0) -> 0 | AX7: =IF(IF(AY8=0,0,AY7-AY8)<=0,0,IF(AY8=0,0,AY7-AY8)) -> 154 | AY7: =VLOOKUP($A16,$A$15:$BQ$26,AY$1,0) -> 45877 | AZ7: =IF(IF(BA8=0,0,BA7-BA8)<=0,0,IF(BA8=0,0,BA7-BA8)) -> 0 | BA7: =VLOOKUP($A16,$A$15:$BQ$26,BA$1,0) -> 0 | BB7: =IF(IF(BC8=0,0,BC7-BC8)<=0,0,IF(BC8=0,0,BC7-BC8)) -> 119 | BC7: =VLOOKUP($A16,$A$15:$BQ$26,BC$1,0) -> 45797 | BD7: =IF(IF(BE8=0,0,BE7-BE8)<=0,0,IF(BE8=0,0,BE7-BE8)) -> 36 | BE7: =VLOOKUP($A16,$A$15:$BQ$26,BE$1,0) -> 45940 | BF7: =IF(IF(BG8=0,0,BG7-BG8)<=0,0,IF(BG8=0,0,BG7-BG8)) -> 45 | BG7: =VLOOKUP($A16,$A$15:$BQ$26,BG$1,0) -> 46003 | BH7: =IF(IF(BI8=0,0,BI7-BI8)<=0,0,IF(BI8=0,0,BI7-BI8)) -> 0 | BI7: =VLOOKUP($A16,$A$15:$BQ$26,BI$1,0) -> 0 | BJ7: =IF(IF(BK8=0,0,BK7-BK8)<=0,0,IF(BK8=0,0,BK7-BK8)) -> 35 | BK7: =VLOOKUP($A16,$A$15:$BQ$26,BK$1,0) -> 46024 | BL7: =IF(IF(BM8=0,0,BM7-BM8)<=0,0,IF(BM8=0,0,BM7-BM8)) -> 0 | BM7: =VLOOKUP($A16,$A$15:$BQ$26,BM$1,0) -> 45300 | BN7: =IF(IF(BO8=0,0,BO7-BO8)<=0,0,IF(BO8=0,0,BO7-BO8)) -> 0 | BO7: =VLOOKUP($A16,$A$15:$BQ$26,BO$1,0) -> 0 | BP7: =IF(IF(BQ8=0,0,BQ7-BQ8)<=0,0,IF(BQ8=0,0,BQ7-BQ8)) -> 0 | BQ7: =VLOOKUP($A16,$A$15:$BQ$26,BQ$1,0) -> 45482
B8: =IF(IF(C9=0,0,C8-C9)<=0,0,IF(C9=0,0,C8-C9)) -> 0 | C8: =VLOOKUP($A17,$A$15:$BQ$26,C$1,0) -> 0 | D8: =IF(IF(E9=0,0,E8-E9)<=0,0,IF(E9=0,0,E8-E9)) -> 7 | E8: =VLOOKUP($A17,$A$15:$BQ$26,E$1,0) -> 45996 | F8: =IF(IF(G9=0,0,G8-G9)<=0,0,IF(G9=0,0,G8-G9)) -> 0 | G8: =VLOOKUP($A17,$A$15:$BQ$26,G$1,0) -> 0 | H8: =IF(IF(I9=0,0,I8-I9)<=0,0,IF(I9=0,0,I8-I9)) -> 0 | I8: =VLOOKUP($A17,$A$15:$BQ$26,I$1,0) -> 0 | J8: =IF(IF(K9=0,0,K8-K9)<=0,0,IF(K9=0,0,K8-K9)) -> 0 | K8: =VLOOKUP($A17,$A$15:$BQ$26,K$1,0) -> 0 | L8: =IF(IF(M9=0,0,M8-M9)<=0,0,IF(M9=0,0,M8-M9)) -> 0 | M8: =VLOOKUP($A17,$A$15:$BQ$26,M$1,0) -> 0 | N8: =IF(IF(O9=0,0,O8-O9)<=0,0,IF(O9=0,0,O8-O9)) -> 0 | O8: =VLOOKUP($A17,$A$15:$BQ$26,O$1,0) -> 45237 | P8: =IF(IF(Q9=0,0,Q8-Q9)<=0,0,IF(Q9=0,0,Q8-Q9)) -> 139 | Q8: =VLOOKUP($A17,$A$15:$BQ$26,Q$1,0) -> 45344 | R8: =IF(IF(S9=0,0,S8-S9)<=0,0,IF(S9=0,0,S8-S9)) -> 11 | S8: =VLOOKUP($A17,$A$15:$BQ$26,S$1,0) -> 45520 | T8: =IF(IF(U9=0,0,U8-U9)<=0,0,IF(U9=0,0,U8-U9)) -> 6 | U8: =VLOOKUP($A17,$A$15:$BQ$26,U$1,0) -> 46030 | V8: =IF(IF(W9=0,0,W8-W9)<=0,0,IF(W9=0,0,W8-W9)) -> 0 | W8: =VLOOKUP($A17,$A$15:$BQ$26,W$1,0) -> 0 | X8: =IF(IF(Y9=0,0,Y8-Y9)<=0,0,IF(Y9=0,0,Y8-Y9)) -> 0 | Y8: =VLOOKUP($A17,$A$15:$BQ$26,Y$1,0) -> 0 | Z8: =IF(IF(AA9=0,0,AA8-AA9)<=0,0,IF(AA9=0,0,AA8-AA9)) -> 58 | AA8: =VLOOKUP($A17,$A$15:$BQ$26,AA$1,0) -> 45736 | AB8: =IF(IF(AC9=0,0,AC8-AC9)<=0,0,IF(AC9=0,0,AC8-AC9)) -> 0 | AC8: =VLOOKUP($A17,$A$15:$BQ$26,AC$1,0) -> 0 | AD8: =IF(IF(AE9=0,0,AE8-AE9)<=0,0,IF(AE9=0,0,AE8-AE9)) -> 0 | AE8: =VLOOKUP($A17,$A$15:$BQ$26,AE$1,0) -> 0 | AF8: =IF(IF(AG9=0,0,AG8-AG9)<=0,0,IF(AG9=0,0,AG8-AG9)) -> 47 | AG8: =VLOOKUP($A17,$A$15:$BQ$26,AG$1,0) -> 45831 | AH8: =IF(IF(AI9=0,0,AI8-AI9)<=0,0,IF(AI9=0,0,AI8-AI9)) -> 0 | AI8: =VLOOKUP($A17,$A$15:$BQ$26,AI$1,0) -> 45218 | AJ8: =IF(IF(AK9=0,0,AK8-AK9)<=0,0,IF(AK9=0,0,AK8-AK9)) -> 0 | AK8: =VLOOKUP($A17,$A$15:$BQ$26,AK$1,0) -> 0 | AL8: =IF(IF(AM9=0,0,AM8-AM9)<=0,0,IF(AM9=0,0,AM8-AM9)) -> 0 | AM8: =VLOOKUP($A17,$A$15:$BQ$26,AM$1,0) -> 0 | AN8: =IF(IF(AO9=0,0,AO8-AO9)<=0,0,IF(AO9=0,0,AO8-AO9)) -> 0 | AO8: =VLOOKUP($A17,$A$15:$BQ$26,AO$1,0) -> 0 | AP8: =IF(IF(AQ9=0,0,AQ8-AQ9)<=0,0,IF(AQ9=0,0,AQ8-AQ9)) -> 0 | AQ8: =VLOOKUP($A17,$A$15:$BQ$26,AQ$1,0) -> 0 | AR8: =IF(AS9=0,0,AS8-AS9) -> 0 | AS8: =VLOOKUP($A17,$A$15:$BQ$26,AS$1,0) -> 45155 | AT8: =IF(IF(AU9=0,0,AU8-AU9)<=0,0,IF(AU9=0,0,AU8-AU9)) -> 73 | AU8: =VLOOKUP($A17,$A$15:$BQ$26,AU$1,0) -> 45344 | AV8: =IF(IF(AW9=0,0,AW8-AW9)<=0,0,IF(AW9=0,0,AW8-AW9)) -> 0 | AW8: =VLOOKUP($A17,$A$15:$BQ$26,AW$1,0) -> 0 | AX8: =IF(IF(AY9=0,0,AY8-AY9)<=0,0,IF(AY9=0,0,AY8-AY9)) -> 45 | AY8: =VLOOKUP($A17,$A$15:$BQ$26,AY$1,0) -> 45723 | AZ8: =IF(IF(BA9=0,0,BA8-BA9)<=0,0,IF(BA9=0,0,BA8-BA9)) -> 0 | BA8: =VLOOKUP($A17,$A$15:$BQ$26,BA$1,0) -> 0 | BB8: =IF(IF(BC9=0,0,BC8-BC9)<=0,0,IF(BC9=0,0,BC8-BC9)) -> 182 | BC8: =VLOOKUP($A17,$A$15:$BQ$26,BC$1,0) -> 45678 | BD8: =IF(IF(BE9=0,0,BE8-BE9)<=0,0,IF(BE9=0,0,BE8-BE9)) -> 195 | BE8: =VLOOKUP($A17,$A$15:$BQ$26,BE$1,0) -> 45904 | BF8: =IF(IF(BG9=0,0,BG8-BG9)<=0,0,IF(BG9=0,0,BG8-BG9)) -> 26 | BG8: =VLOOKUP($A17,$A$15:$BQ$26,BG$1,0) -> 45958 | BH8: =IF(IF(BI9=0,0,BI8-BI9)<=0,0,IF(BI9=0,0,BI8-BI9)) -> 0 | BI8: =VLOOKUP($A17,$A$15:$BQ$26,BI$1,0) -> 0 | BJ8: =IF(IF(BK9=0,0,BK8-BK9)<=0,0,IF(BK9=0,0,BK8-BK9)) -> 14 | BK8: =VLOOKUP($A17,$A$15:$BQ$26,BK$1,0) -> 45989 | BL8: =IF(IF(BM9=0,0,BM8-BM9)<=0,0,IF(BM9=0,0,BM8-BM9)) -> 0 | BM8: =VLOOKUP($A17,$A$15:$BQ$26,BM$1,0) -> 0 | BN8: =IF(IF(BO9=0,0,BO8-BO9)<=0,0,IF(BO9=0,0,BO8-BO9)) -> 0 | BO8: =VLOOKUP($A17,$A$15:$BQ$26,BO$1,0) -> 0 | BP8: =IF(IF(BQ9=0,0,BQ8-BQ9)<=0,0,IF(BQ9=0,0,BQ8-BQ9)) -> 0 | BQ8: =VLOOKUP($A17,$A$15:$BQ$26,BQ$1,0) -> 0
